Workbook

Sheet Özet
A1: BİGETAŞ BİYOTEKNOLOJİ A.Ş. — NAKİT AKIŞI & AYLIK CİRO HEDEFİ
A2: Hazırlık: 25.08.2026 · Kaynak: Vakıfbank ödeme planları (6 kredi) + QNB ödeme planı (1 kredi) + kullanıcının gider ve satış verileri. Tüm rakamlar formül; Varsayımlar sayfasını güncelleyince yenilenir.
A3: Renk kodu: Mavi = girdi · Sarı = teyit edilecek varsayım · Siyah = formül · Yeşil = başka sayfadan link
A5: BUGÜNKÜ DURUM — mevcut ciro ve giderlerle (Eyl 2026)
A6: Mevcut aylık ciro (E-ticaret + Toptan/fason + Hammadde + Migros) | B6: =Varsayımlar!$B$37 -> 1650000
A7: Ağırlıklı brüt (katkı) marjı | B7: =Varsayımlar!$B$5 -> 0.4969697
A8: Aylık brüt kâr | B8: ='Nakit Akışı'!$B$14 -> 820000
A9: Aylık sabit gider | B9: =Varsayımlar!$B$29 -> 411000
A10: FAVÖK (brüt kâr − sabit gider) | B10: ='Nakit Akışı'!$B$34 -> 409000
A11: Kredi taksiti (faiz + anapara) | B11: ='Nakit Akışı'!$B$36+'Nakit Akışı'!$B$41 -> -325778.41
A12: Kurumlar vergisi (basitleştirilmiş) | B12: ='Nakit Akışı'!$B$38 -> -49943.563
A13: AYLIK NET NAKİT — Eyl 2026 | B13: ='Nakit Akışı'!$B$45 -> 33278.03
A14: Aylık net nakit — ilk 12 ay ortalaması | B14: =AVERAGE('Nakit Akışı'!$B$45:$M$45) -> 33970.702
A15: Aylık net nakit — Tem 2028 sonrası (iki kredi bitince) | B15: ='Nakit Akışı'!$X$45 -> 112862.26
A17: AYLIK CİRO HEDEFİ (KDV hariç, TL) — mevcut kanal karışımıyla
A18: Sadece kredi taksitlerini karşılamak için gereken ciro — Eyl 2026 | B18: ='Nakit Akışı'!$B$50 -> 655529.72
A19: HEDEF AYLIK CİRO — Eyl 2026 (sabit gider + taksit + vergi + tampon) | B19: ='Nakit Akışı'!$B$49 -> 1560717.5
A20: Mevcut ciro − hedef (eksi = açık) | B20: ='Nakit Akışı'!$B$51 -> 89282.519
A21: Hedefin kanal payı — E-ticaret (mevcut oranla) | B21: =$B$19*Varsayımlar!$B$33/Varsayımlar!$B$37 -> 733064.27
A22: Hedefin kanal payı — Toptan / fason (mevcut oranla) | B22: =$B$19*Varsayımlar!$B$34/Varsayımlar!$B$37 -> 709417.04
A23: Hedefin kanal payı — Doğrudan hammadde satışı (mevcut oranla) | B23: =$B$19*Varsayımlar!$B$35/Varsayımlar!$B$37 -> 70941.704
A24: Hedefin kanal payı — Migros (mevcut oranla) | B24: =$B$19*Varsayımlar!$B$36/Varsayımlar!$B$37 -> 47294.469
A25: Hedef aylık ciro — ilk 12 ay ortalaması (Eyl 2026 – Ağu 2027) | B25: =AVERAGE('Nakit Akışı'!$B$49:$M$49) -> 1558859.1
A26: Hedef aylık ciro — 2027 ortalaması | B26: =AVERAGE('Nakit Akışı'!$F$49:$Q$49) -> 1563456.3
A27: Hedef aylık ciro — 2028 ortalaması | B27: =AVERAGE('Nakit Akışı'!$R$49:$AC$49) -> 1462134
A28: Hedef aylık ciro — Oca–Ağu 2029 ortalaması | B28: =AVERAGE('Nakit Akışı'!$AD$49:$AK$49) -> 1298335.9
A30: DUYARLILIK 1 — toptan/fason cirosuna göre aylık net nakit (diğer kanallar sabit)
A31: Toptan/fason aylık ciro | B31: Toplam ciro | C31: Net nakit — Eyl 2026 | D31: Net nakit — 2027 ort. | E31: Net nakit — Tem 2028 sonrası
A32: 250000 | B32: =(Varsayımlar!$B$33*Varsayımlar!$B$9)+$A32+(Varsayımlar!$B$35*Varsayımlar!$B$9)+(Varsayımlar!$B$36*Varsayımlar!$B$9) -> 1150000 | C32: =(((Varsayımlar!$B$33*Varsayımlar!$B$9)*Varsayımlar!$C$33+$A32*Varsayımlar!$C$34+(Varsayımlar!$B$35*Varsayımlar!$B$9)*Varsayımlar!$C$35+(Varsayımlar!$B$36*Varsayımlar!$B$9)*Varsayımlar!$C$36)+'Nakit Akışı'!$B$33+'Nakit Akışı'!$B$36)-MAX(0,(((Varsayımlar!$B$33*Varsayımlar!$B$9)*Varsayımlar!$C$33+$A32*Varsayımlar!$C$34+(Varsayımlar!$B$35*Varsayımlar!$B$9)*Varsayımlar!$C$35+(Varsayımlar!$B$36*Varsayımlar!$B$9)*Varsayımlar!$C$36)+'Nakit Akışı'!$B$33+'Nakit Akışı'!$B$36))*Varsayımlar!$B$7+'Nakit Akışı'!$B$41-((Varsayımlar!$B$33*Varsayımlar!$B$9)+$A32+(Varsayımlar!$B$35*Varsayımlar!$B$9)+(Varsayımlar!$B$36*Varsayımlar!$B$9))*Varsayımlar!$B$6 -> -226778.41 | D32: =(((Varsayımlar!$B$33*Varsayımlar!$B$9)*Varsayımlar!$C$33+$A32*Varsayımlar!$C$34+(Varsayımlar!$B$35*Varsayımlar!$B$9)*Varsayımlar!$C$35+(Varsayımlar!$B$36*Varsayımlar!$B$9)*Varsayımlar!$C$36)+AVERAGE('Nakit Akışı'!$F$33:$Q$33)+AVERAGE('Nakit Akışı'!$F$36:$Q$36))-MAX(0,(((Varsayımlar!$B$33*Varsayımlar!$B$9)*Varsayımlar!$C$33+$A32*Varsayımlar!$C$34+(Varsayımlar!$B$35*Varsayımlar!$B$9)*Varsayımlar!$C$35+(Varsayımlar!$B$36*Varsayımlar!$B$9)*Varsayımlar!$C$36)+AVERAGE('Nakit Akışı'!$F$33:$Q$33)+AVERAGE('Nakit Akışı'!$F$36:$Q$36)))*Varsayımlar!$B$7+AVERAGE('Nakit Akışı'!$F$41:$Q$41)-((Varsayımlar!$B$33*Varsayımlar!$B$9)+$A32+(Varsayımlar!$B$35*Varsayımlar!$B$9)+(Varsayımlar!$B$36*Varsayımlar!$B$9))*Varsayımlar!$B$6 -> -216220.26 | E32: =(((Varsayımlar!$B$33*Varsayımlar!$B$9)*Varsayımlar!$C$33+$A32*Varsayımlar!$C$34+(Varsayımlar!$B$35*Varsayımlar!$B$9)*Varsayımlar!$C$35+(Varsayımlar!$B$36*Varsayımlar!$B$9)*Varsayımlar!$C$36)+'Nakit Akışı'!$X$33+'Nakit Akışı'!$X$36)-MAX(0,(((Varsayımlar!$B$33*Varsayımlar!$B$9)*Varsayımlar!$C$33+$A32*Varsayımlar!$C$34+(Varsayımlar!$B$35*Varsayımlar!$B$9)*Varsayımlar!$C$35+(Varsayımlar!$B$36*Varsayımlar!$B$9)*Varsayımlar!$C$36)+'Nakit Akışı'!$X$33+'Nakit Akışı'!$X$36))*Varsayımlar!$B$7+'Nakit Akışı'!$X$41-((Varsayımlar!$B$33*Varsayımlar!$B$9)+$A32+(Varsayımlar!$B$35*Varsayımlar!$B$9)+(Varsayımlar!$B$36*Varsayımlar!$B$9))*Varsayımlar!$B$6 -> -119637.74
A33: 500000 | B33: =(Varsayımlar!$B$33*Varsayımlar!$B$9)+$A33+(Varsayımlar!$B$35*Varsayımlar!$B$9)+(Varsayımlar!$B$36*Varsayımlar!$B$9) -> 1400000 | C33: =(((Varsayımlar!$B$33*Varsayımlar!$B$9)*Varsayımlar!$C$33+$A33*Varsayımlar!$C$34+(Varsayımlar!$B$35*Varsayımlar!$B$9)*Varsayımlar!$C$35+(Varsayımlar!$B$36*Varsayımlar!$B$9)*Varsayımlar!$C$36)+'Nakit Akışı'!$B$33+'Nakit Akışı'!$B$36)-MAX(0,(((Varsayımlar!$B$33*Varsayımlar!$B$9)*Varsayımlar!$C$33+$A33*Varsayımlar!$C$34+(Varsayımlar!$B$35*Varsayımlar!$B$9)*Varsayımlar!$C$35+(Varsayımlar!$B$36*Varsayımlar!$B$9)*Varsayımlar!$C$36)+'Nakit Akışı'!$B$33+'Nakit Akışı'!$B$36))*Varsayımlar!$B$7+'Nakit Akışı'!$B$41-((Varsayımlar!$B$33*Varsayımlar!$B$9)+$A33+(Varsayımlar!$B$35*Varsayımlar!$B$9)+(Varsayımlar!$B$36*Varsayımlar!$B$9))*Varsayımlar!$B$6 -> -82971.97 | D33: =(((Varsayımlar!$B$33*Varsayımlar!$B$9)*Varsayımlar!$C$33+$A33*Varsayımlar!$C$34+(Varsayımlar!$B$35*Varsayımlar!$B$9)*Varsayımlar!$C$35+(Varsayımlar!$B$36*Varsayımlar!$B$9)*Varsayımlar!$C$36)+AVERAGE('Nakit Akışı'!$F$33:$Q$33)+AVERAGE('Nakit Akışı'!$F$36:$Q$36))-MAX(0,(((Varsayımlar!$B$33*Varsayımlar!$B$9)*Varsayımlar!$C$33+$A33*Varsayımlar!$C$34+(Varsayımlar!$B$35*Varsayımlar!$B$9)*Varsayımlar!$C$35+(Varsayımlar!$B$36*Varsayımlar!$B$9)*Varsayımlar!$C$36)+AVERAGE('Nakit Akışı'!$F$33:$Q$33)+AVERAGE('Nakit Akışı'!$F$36:$Q$36)))*Varsayımlar!$B$7+AVERAGE('Nakit Akışı'!$F$41:$Q$41)-((Varsayımlar!$B$33*Varsayımlar!$B$9)+$A33+(Varsayımlar!$B$35*Varsayımlar!$B$9)+(Varsayımlar!$B$36*Varsayımlar!$B$9))*Varsayımlar!$B$6 -> -83992.814 | E33: =(((Varsayımlar!$B$33*Varsayımlar!$B$9)*Varsayımlar!$C$33+$A33*Varsayımlar!$C$34+(Varsayımlar!$B$35*Varsayımlar!$B$9)*Varsayımlar!$C$35+(Varsayımlar!$B$36*Varsayımlar!$B$9)*Varsayımlar!$C$36)+'Nakit Akışı'!$X$33+'Nakit Akışı'!$X$36)-MAX(0,(((Varsayımlar!$B$33*Varsayımlar!$B$9)*Varsayımlar!$C$33+$A33*Varsayımlar!$C$34+(Varsayımlar!$B$35*Varsayımlar!$B$9)*Varsayımlar!$C$35+(Varsayımlar!$B$36*Varsayımlar!$B$9)*Varsayımlar!$C$36)+'Nakit Akışı'!$X$33+'Nakit Akışı'!$X$36))*Varsayımlar!$B$7+'Nakit Akışı'!$X$41-((Varsayımlar!$B$33*Varsayımlar!$B$9)+$A33+(Varsayımlar!$B$35*Varsayımlar!$B$9)+(Varsayımlar!$B$36*Varsayımlar!$B$9))*Varsayımlar!$B$6 -> -3387.735
A34: 750000 | B34: =(Varsayımlar!$B$33*Varsayımlar!$B$9)+$A34+(Varsayımlar!$B$35*Varsayımlar!$B$9)+(Varsayımlar!$B$36*Varsayımlar!$B$9) -> 1650000 | C34: =(((Varsayımlar!$B$33*Varsayımlar!$B$9)*Varsayımlar!$C$33+$A34*Varsayımlar!$C$34+(Varsayımlar!$B$35*Varsayımlar!$B$9)*Varsayımlar!$C$35+(Varsayımlar!$B$36*Varsayımlar!$B$9)*Varsayımlar!$C$36)+'Nakit Akışı'!$B$33+'Nakit Akışı'!$B$36)-MAX(0,(((Varsayımlar!$B$33*Varsayımlar!$B$9)*Varsayımlar!$C$33+$A34*Varsayımlar!$C$34+(Varsayımlar!$B$35*Varsayımlar!$B$9)*Varsayımlar!$C$35+(Varsayımlar!$B$36*Varsayımlar!$B$9)*Varsayımlar!$C$36)+'Nakit Akışı'!$B$33+'Nakit Akışı'!$B$36))*Varsayımlar!$B$7+'Nakit Akışı'!$B$41-((Varsayımlar!$B$33*Varsayımlar!$B$9)+$A34+(Varsayımlar!$B$35*Varsayımlar!$B$9)+(Varsayımlar!$B$36*Varsayımlar!$B$9))*Varsayımlar!$B$6 -> 33278.03 | D34: =(((Varsayımlar!$B$33*Varsayımlar!$B$9)*Varsayımlar!$C$33+$A34*Varsayımlar!$C$34+(Varsayımlar!$B$35*Varsayımlar!$B$9)*Varsayımlar!$C$35+(Varsayımlar!$B$36*Varsayımlar!$B$9)*Varsayımlar!$C$36)+AVERAGE('Nakit Akışı'!$F$33:$Q$33)+AVERAGE('Nakit Akışı'!$F$36:$Q$36))-MAX(0,(((Varsayımlar!$B$33*Varsayımlar!$B$9)*Varsayımlar!$C$33+$A34*Varsayımlar!$C$34+(Varsayımlar!$B$35*Varsayımlar!$B$9)*Varsayımlar!$C$35+(Varsayımlar!$B$36*Varsayımlar!$B$9)*Varsayımlar!$C$36)+AVERAGE('Nakit Akışı'!$F$33:$Q$33)+AVERAGE('Nakit Akışı'!$F$36:$Q$36)))*Varsayımlar!$B$7+AVERAGE('Nakit Akışı'!$F$41:$Q$41)-((Varsayımlar!$B$33*Varsayımlar!$B$9)+$A34+(Varsayımlar!$B$35*Varsayımlar!$B$9)+(Varsayımlar!$B$36*Varsayımlar!$B$9))*Varsayımlar!$B$6 -> 32257.186 | E34: =(((Varsayımlar!$B$33*Varsayımlar!$B$9)*Varsayımlar!$C$33+$A34*Varsayımlar!$C$34+(Varsayımlar!$B$35*Varsayımlar!$B$9)*Varsayımlar!$C$35+(Varsayımlar!$B$36*Varsayımlar!$B$9)*Varsayımlar!$C$36)+'Nakit Akışı'!$X$33+'Nakit Akışı'!$X$36)-MAX(0,(((Varsayımlar!$B$33*Varsayımlar!$B$9)*Varsayımlar!$C$33+$A34*Varsayımlar!$C$34+(Varsayımlar!$B$35*Varsayımlar!$B$9)*Varsayımlar!$C$35+(Varsayımlar!$B$36*Varsayımlar!$B$9)*Varsayımlar!$C$36)+'Nakit Akışı'!$X$33+'Nakit Akışı'!$X$36))*Varsayımlar!$B$7+'Nakit Akışı'!$X$41-((Varsayımlar!$B$33*Varsayımlar!$B$9)+$A34+(Varsayımlar!$B$35*Varsayımlar!$B$9)+(Varsayımlar!$B$36*Varsayımlar!$B$9))*Varsayımlar!$B$6 -> 112862.26
A35: 1000000 | B35: =(Varsayımlar!$B$33*Varsayımlar!$B$9)+$A35+(Varsayımlar!$B$35*Varsayımlar!$B$9)+(Varsayımlar!$B$36*Varsayımlar!$B$9) -> 1900000 | C35: =(((Varsayımlar!$B$33*Varsayımlar!$B$9)*Varsayımlar!$C$33+$A35*Varsayımlar!$C$34+(Varsayımlar!$B$35*Varsayımlar!$B$9)*Varsayımlar!$C$35+(Varsayımlar!$B$36*Varsayımlar!$B$9)*Varsayımlar!$C$36)+'Nakit Akışı'!$B$33+'Nakit Akışı'!$B$36)-MAX(0,(((Varsayımlar!$B$33*Varsayımlar!$B$9)*Varsayımlar!$C$33+$A35*Varsayımlar!$C$34+(Varsayımlar!$B$35*Varsayımlar!$B$9)*Varsayımlar!$C$35+(Varsayımlar!$B$36*Varsayımlar!$B$9)*Varsayımlar!$C$36)+'Nakit Akışı'!$B$33+'Nakit Akışı'!$B$36))*Varsayımlar!$B$7+'Nakit Akışı'!$B$41-((Varsayımlar!$B$33*Varsayımlar!$B$9)+$A35+(Varsayımlar!$B$35*Varsayımlar!$B$9)+(Varsayımlar!$B$36*Varsayımlar!$B$9))*Varsayımlar!$B$6 -> 149528.03 | D35: =(((Varsayımlar!$B$33*Varsayımlar!$B$9)*Varsayımlar!$C$33+$A35*Varsayımlar!$C$34+(Varsayımlar!$B$35*Varsayımlar!$B$9)*Varsayımlar!$C$35+(Varsayımlar!$B$36*Varsayımlar!$B$9)*Varsayımlar!$C$36)+AVERAGE('Nakit Akışı'!$F$33:$Q$33)+AVERAGE('Nakit Akışı'!$F$36:$Q$36))-MAX(0,(((Varsayımlar!$B$33*Varsayımlar!$B$9)*Varsayımlar!$C$33+$A35*Varsayımlar!$C$34+(Varsayımlar!$B$35*Varsayımlar!$B$9)*Varsayımlar!$C$35+(Varsayımlar!$B$36*Varsayımlar!$B$9)*Varsayımlar!$C$36)+AVERAGE('Nakit Akışı'!$F$33:$Q$33)+AVERAGE('Nakit Akışı'!$F$36:$Q$36)))*Varsayımlar!$B$7+AVERAGE('Nakit Akışı'!$F$41:$Q$41)-((Varsayımlar!$B$33*Varsayımlar!$B$9)+$A35+(Varsayımlar!$B$35*Varsayımlar!$B$9)+(Varsayımlar!$B$36*Varsayımlar!$B$9))*Varsayımlar!$B$6 -> 148507.19 | E35: =(((Varsayımlar!$B$33*Varsayımlar!$B$9)*Varsayımlar!$C$33+$A35*Varsayımlar!$C$34+(Varsayımlar!$B$35*Varsayımlar!$B$9)*Varsayımlar!$C$35+(Varsayımlar!$B$36*Varsayımlar!$B$9)*Varsayımlar!$C$36)+'Nakit Akışı'!$X$33+'Nakit Akışı'!$X$36)-MAX(0,(((Varsayımlar!$B$33*Varsayımlar!$B$9)*Varsayımlar!$C$33+$A35*Varsayımlar!$C$34+(Varsayımlar!$B$35*Varsayımlar!$B$9)*Varsayımlar!$C$35+(Varsayımlar!$B$36*Varsayımlar!$B$9)*Varsayımlar!$C$36)+'Nakit Akışı'!$X$33+'Nakit Akışı'!$X$36))*Varsayımlar!$B$7+'Nakit Akışı'!$X$41-((Varsayımlar!$B$33*Varsayımlar!$B$9)+$A35+(Varsayımlar!$B$35*Varsayımlar!$B$9)+(Varsayımlar!$B$36*Varsayımlar!$B$9))*Varsayımlar!$B$6 -> 229112.27
A36: 1250000 | B36: =(Varsayımlar!$B$33*Varsayımlar!$B$9)+$A36+(Varsayımlar!$B$35*Varsayımlar!$B$9)+(Varsayımlar!$B$36*Varsayımlar!$B$9) -> 2150000 | C36: =(((Varsayımlar!$B$33*Varsayımlar!$B$9)*Varsayımlar!$C$33+$A36*Varsayımlar!$C$34+(Varsayımlar!$B$35*Varsayımlar!$B$9)*Varsayımlar!$C$35+(Varsayımlar!$B$36*Varsayımlar!$B$9)*Varsayımlar!$C$36)+'Nakit Akışı'!$B$33+'Nakit Akışı'!$B$36)-MAX(0,(((Varsayımlar!$B$33*Varsayımlar!$B$9)*Varsayımlar!$C$33+$A36*Varsayımlar!$C$34+(Varsayımlar!$B$35*Varsayımlar!$B$9)*Varsayımlar!$C$35+(Varsayımlar!$B$36*Varsayımlar!$B$9)*Varsayımlar!$C$36)+'Nakit Akışı'!$B$33+'Nakit Akışı'!$B$36))*Varsayımlar!$B$7+'Nakit Akışı'!$B$41-((Varsayımlar!$B$33*Varsayımlar!$B$9)+$A36+(Varsayımlar!$B$35*Varsayımlar!$B$9)+(Varsayımlar!$B$36*Varsayımlar!$B$9))*Varsayımlar!$B$6 -> 265778.03 | D36: =(((Varsayımlar!$B$33*Varsayımlar!$B$9)*Varsayımlar!$C$33+$A36*Varsayımlar!$C$34+(Varsayımlar!$B$35*Varsayımlar!$B$9)*Varsayımlar!$C$35+(Varsayımlar!$B$36*Varsayımlar!$B$9)*Varsayımlar!$C$36)+AVERAGE('Nakit Akışı'!$F$33:$Q$33)+AVERAGE('Nakit Akışı'!$F$36:$Q$36))-MAX(0,(((Varsayımlar!$B$33*Varsayımlar!$B$9)*Varsayımlar!$C$33+$A36*Varsayımlar!$C$34+(Varsayımlar!$B$35*Varsayımlar!$B$9)*Varsayımlar!$C$35+(Varsayımlar!$B$36*Varsayımlar!$B$9)*Varsayımlar!$C$36)+AVERAGE('Nakit Akışı'!$F$33:$Q$33)+AVERAGE('Nakit Akışı'!$F$36:$Q$36)))*Varsayımlar!$B$7+AVERAGE('Nakit Akışı'!$F$41:$Q$41)-((Varsayımlar!$B$33*Varsayımlar!$B$9)+$A36+(Varsayımlar!$B$35*Varsayımlar!$B$9)+(Varsayımlar!$B$36*Varsayımlar!$B$9))*Varsayımlar!$B$6 -> 264757.19 | E36: =(((Varsayımlar!$B$33*Varsayımlar!$B$9)*Varsayımlar!$C$33+$A36*Varsayımlar!$C$34+(Varsayımlar!$B$35*Varsayımlar!$B$9)*Varsayımlar!$C$35+(Varsayımlar!$B$36*Varsayımlar!$B$9)*Varsayımlar!$C$36)+'Nakit Akışı'!$X$33+'Nakit Akışı'!$X$36)-MAX(0,(((Varsayımlar!$B$33*Varsayımlar!$B$9)*Varsayımlar!$C$33+$A36*Varsayımlar!$C$34+(Varsayımlar!$B$35*Varsayımlar!$B$9)*Varsayımlar!$C$35+(Varsayımlar!$B$36*Varsayımlar!$B$9)*Varsayımlar!$C$36)+'Nakit Akışı'!$X$33+'Nakit Akışı'!$X$36))*Varsayımlar!$B$7+'Nakit Akışı'!$X$41-((Varsayımlar!$B$33*Varsayımlar!$B$9)+$A36+(Varsayımlar!$B$35*Varsayımlar!$B$9)+(Varsayımlar!$B$36*Varsayımlar!$B$9))*Varsayımlar!$B$6 -> 345362.27
A38: DUYARLILIK 2 — ağırlıklı brüt marja göre gereken aylık ciro (TL)
A39: Ağırlıklı brüt marj | B39: Sadece kredi taksiti (Eyl–Ara 2026) | C39: Hedef ciro — Eyl 2026 | D39: Hedef ciro — 2027 ort. | E39: Hedef ciro — Tem 2028 sonrası
A40: 0.35 | B40: =INDEX('Kredi Takvimi'!$Y$4:$Y$40,MATCH("Eyl 2026",'Kredi Takvimi'!$A$4:$A$40,0))/$A40 -> 930795.45 | C40: =IF(($A40*(1-Varsayımlar!$B$7)-Varsayımlar!$B$6)>0,((-'Nakit Akışı'!$B$41+Varsayımlar!$B$8)+(-'Nakit Akışı'!$B$33-'Nakit Akışı'!$B$36)*(1-Varsayımlar!$B$7))/($A40*(1-Varsayımlar!$B$7)-Varsayımlar!$B$6),0) -> 2216083.7 | D40: =IF(($A40*(1-Varsayımlar!$B$7)-Varsayımlar!$B$6)>0,((-AVERAGE('Nakit Akışı'!$F$41:$Q$41)+Varsayımlar!$B$8)+(-AVERAGE('Nakit Akışı'!$F$33:$Q$33)-AVERAGE('Nakit Akışı'!$F$36:$Q$36))*(1-Varsayımlar!$B$7))/($A40*(1-Varsayımlar!$B$7)-Varsayımlar!$B$6),0) -> 2219972.6 | E40: =IF(($A40*(1-Varsayımlar!$B$7)-Varsayımlar!$B$6)>0,((-'Nakit Akışı'!$X$41+Varsayımlar!$B$8)+(-'Nakit Akışı'!$X$33-'Nakit Akışı'!$X$36)*(1-Varsayımlar!$B$7))/($A40*(1-Varsayımlar!$B$7)-Varsayımlar!$B$6),0) -> 1912905.7
A41: 0.4 | B41: =INDEX('Kredi Takvimi'!$Y$4:$Y$40,MATCH("Eyl 2026",'Kredi Takvimi'!$A$4:$A$40,0))/$A41 -> 814446.02 | C41: =IF(($A41*(1-Varsayımlar!$B$7)-Varsayımlar!$B$6)>0,((-'Nakit Akışı'!$B$41+Varsayımlar!$B$8)+(-'Nakit Akışı'!$B$33-'Nakit Akışı'!$B$36)*(1-Varsayımlar!$B$7))/($A41*(1-Varsayımlar!$B$7)-Varsayımlar!$B$6),0) -> 1939073.2 | D41: =IF(($A41*(1-Varsayımlar!$B$7)-Varsayımlar!$B$6)>0,((-AVERAGE('Nakit Akışı'!$F$41:$Q$41)+Varsayımlar!$B$8)+(-AVERAGE('Nakit Akışı'!$F$33:$Q$33)-AVERAGE('Nakit Akışı'!$F$36:$Q$36))*(1-Varsayımlar!$B$7))/($A41*(1-Varsayımlar!$B$7)-Varsayımlar!$B$6),0) -> 1942476 | E41: =IF(($A41*(1-Varsayımlar!$B$7)-Varsayımlar!$B$6)>0,((-'Nakit Akışı'!$X$41+Varsayımlar!$B$8)+(-'Nakit Akışı'!$X$33-'Nakit Akışı'!$X$36)*(1-Varsayımlar!$B$7))/($A41*(1-Varsayımlar!$B$7)-Varsayımlar!$B$6),0) -> 1673792.4
A42: 0.45 | B42: =INDEX('Kredi Takvimi'!$Y$4:$Y$40,MATCH("Eyl 2026",'Kredi Takvimi'!$A$4:$A$40,0))/$A42 -> 723952.02 | C42: =IF(($A42*(1-Varsayımlar!$B$7)-Varsayımlar!$B$6)>0,((-'Nakit Akışı'!$B$41+Varsayımlar!$B$8)+(-'Nakit Akışı'!$B$33-'Nakit Akışı'!$B$36)*(1-Varsayımlar!$B$7))/($A42*(1-Varsayımlar!$B$7)-Varsayımlar!$B$6),0) -> 1723620.7 | D42: =IF(($A42*(1-Varsayımlar!$B$7)-Varsayımlar!$B$6)>0,((-AVERAGE('Nakit Akışı'!$F$41:$Q$41)+Varsayımlar!$B$8)+(-AVERAGE('Nakit Akışı'!$F$33:$Q$33)-AVERAGE('Nakit Akışı'!$F$36:$Q$36))*(1-Varsayımlar!$B$7))/($A42*(1-Varsayımlar!$B$7)-Varsayımlar!$B$6),0) -> 1726645.4 | E42: =IF(($A42*(1-Varsayımlar!$B$7)-Varsayımlar!$B$6)>0,((-'Nakit Akışı'!$X$41+Varsayımlar!$B$8)+(-'Nakit Akışı'!$X$33-'Nakit Akışı'!$X$36)*(1-Varsayımlar!$B$7))/($A42*(1-Varsayımlar!$B$7)-Varsayımlar!$B$6),0) -> 1487815.5
A43: 0.5 | B43: =INDEX('Kredi Takvimi'!$Y$4:$Y$40,MATCH("Eyl 2026",'Kredi Takvimi'!$A$4:$A$40,0))/$A43 -> 651556.81 | C43: =IF(($A43*(1-Varsayımlar!$B$7)-Varsayımlar!$B$6)>0,((-'Nakit Akışı'!$B$41+Varsayımlar!$B$8)+(-'Nakit Akışı'!$B$33-'Nakit Akışı'!$B$36)*(1-Varsayımlar!$B$7))/($A43*(1-Varsayımlar!$B$7)-Varsayımlar!$B$6),0) -> 1551258.6 | D43: =IF(($A43*(1-Varsayımlar!$B$7)-Varsayımlar!$B$6)>0,((-AVERAGE('Nakit Akışı'!$F$41:$Q$41)+Varsayımlar!$B$8)+(-AVERAGE('Nakit Akışı'!$F$33:$Q$33)-AVERAGE('Nakit Akışı'!$F$36:$Q$36))*(1-Varsayımlar!$B$7))/($A43*(1-Varsayımlar!$B$7)-Varsayımlar!$B$6),0) -> 1553980.8 | E43: =IF(($A43*(1-Varsayımlar!$B$7)-Varsayımlar!$B$6)>0,((-'Nakit Akışı'!$X$41+Varsayımlar!$B$8)+(-'Nakit Akışı'!$X$33-'Nakit Akışı'!$X$36)*(1-Varsayımlar!$B$7))/($A43*(1-Varsayımlar!$B$7)-Varsayımlar!$B$6),0) -> 1339034
A44: 0.55 | B44: =INDEX('Kredi Takvimi'!$Y$4:$Y$40,MATCH("Eyl 2026",'Kredi Takvimi'!$A$4:$A$40,0))/$A44 -> 592324.38 | C44: =IF(($A44*(1-Varsayımlar!$B$7)-Varsayımlar!$B$6)>0,((-'Nakit Akışı'!$B$41+Varsayımlar!$B$8)+(-'Nakit Akışı'!$B$33-'Nakit Akışı'!$B$36)*(1-Varsayımlar!$B$7))/($A44*(1-Varsayımlar!$B$7)-Varsayımlar!$B$6),0) -> 1410235.1 | D44: =IF(($A44*(1-Varsayımlar!$B$7)-Varsayımlar!$B$6)>0,((-AVERAGE('Nakit Akışı'!$F$41:$Q$41)+Varsayımlar!$B$8)+(-AVERAGE('Nakit Akışı'!$F$33:$Q$33)-AVERAGE('Nakit Akışı'!$F$36:$Q$36))*(1-Varsayımlar!$B$7))/($A44*(1-Varsayımlar!$B$7)-Varsayımlar!$B$6),0) -> 1412709.9 | E44: =IF(($A44*(1-Varsayımlar!$B$7)-Varsayımlar!$B$6)>0,((-'Nakit Akışı'!$X$41+Varsayımlar!$B$8)+(-'Nakit Akışı'!$X$33-'Nakit Akışı'!$X$36)*(1-Varsayımlar!$B$7))/($A44*(1-Varsayımlar!$B$7)-Varsayımlar!$B$6),0) -> 1217303.6
...

Sheet Varsayımlar
A1: VARSAYIMLAR — mavi hücreleri güncelle, formüller kendini yeniler
A2: Mavi yazı = girdi (kullanıcı verisi 25.08.2026 veya varsayım). Sarı = tahminî, teyit et. Siyah = formül. Sabit giderler KDV dahil (devreden KDV).
A3: Genel
A4: Dönem başı nakit — 1 Eyl 2026 (banka + kasa, TL) | B4: 0 | E4: 29.08.2026 Vakıf 500k taksiti (41.163,97 TL) ödendikten sonraki toplam bakiye — GİR
A5: Ağırlıklı brüt (katkı) marjı — kanal karışımından | B5: =C37 -> 0.4969697 | E5: Formül: kanal cirolarıyla ağırlıklı (aşağıdaki tablo). Hedef ciro bu marjla hesaplanır
A6: Net KDV ödemesi (ciro %) | B6: 0 | E6: Kullanıcı: satışlar %1 KDV, alımlar %20 → devreden KDV birikiyor, nakit KDV ödemesi yok → 0. Giderler KDV dahil yazıldı
A7: Kurumlar vergisi oranı | B7: 0.25 | E7: Basitleştirme: aylık tahakkuk; amortisman ve geçmiş yıl zararı yok. Zarar mahsubu varsa 0 yapabilirsin
A8: Aylık nakit tampon hedefi (TL) | B8: 0 | E8: Hedef ciroya eklenen aylık net nakit fazlası (0 = tam başabaş)
A9: Ciro senaryo çarpanı (1,00 = mevcut ciro) | B9: 1 | E9: Tüm kanalları ölçekler: 1,20 = %20 büyüme senaryosu
A10: Aylık ciro büyümesi % | B10: 0 | E10: Eyl 2026’dan itibaren aylık bileşik
A11: Sabit gider yıllık artış % | B11: 0 | E11: Her 12 ayda bir uygulanır (Eyl 2027, Eyl 2028). Enflasyon için %25–30 girebilirsin
A13: Aylık sabit giderler (TL, KDV dahil) — kullanıcı verisi, 25.08.2026
A14: Kira — fabrika (KDV dahil) | B14: 150000 | E14: Kullanıcı: ~150.000 KDV dahil; devreden KDV birikimi nedeniyle KDV dahil yazıldı
A15: OSB / site aidatı | B15: 7000 | E15: Kullanıcı verisi
A16: Personel — mevcut maaşlar (kurucu maaşı dahil) | B16: 110000 | E16: Kullanıcı verisi
A17: Personel — stopaj / SGK | B17: 30000 | E17: Kullanıcı verisi
A18: Personel — planlanan part-time | B18: 20000 | E18: Kullanıcı: toplam personel maliyeti ~160.000 olacak
A19: Enerji (elektrik, su, gaz) | B19: 15000 | E19: Kullanıcı verisi
A20: Muhasebe / mali müşavir | B20: 10000 | E20: Kullanıcı verisi
A21: Yazılım abonelikleri | B21: 3000 | E21: Kullanıcı verisi
A22: Sigorta (şu an yalnız araç) | B22: 3000 | E22: Kullanıcı verisi
A23: Bakım-onarım, temizlik, güvenlik | B23: 10000 | E23: Kullanıcı verisi
A24: İnternet, telefon | B24: 1000 | E24: Kullanıcı verisi
A25: Belgeler, analiz, sertifika | B25: 5000 | E25: Kullanıcı verisi
... A28: Banka masrafları | B28: 2000 | E28: Kullanıcı verisi
A29: Toplam aylık sabit gider | B29: =SUM(B14:B28) -> 411000
A31: Satış kanalları — mevcut aylık ciro (KDV hariç), katkı marjı, tahsilat vadesi — kullanıcı verisi, 25.08.2026
A32: Kanal | B32: Aylık ciro (TL) | C32: Katkı marjı % | D32: Tahsilat vadesi (ay) | E32: Kaynak / hesap
A33: E-ticaret (Trendyol, Hepsiburada, kendi site) | B33: 775000 | C33: 0.4 | D33: 0 | E33: Kullanıcı: 750–800k/ay (Hepsiburada tek başına ~500k). Marj: 450 TL satış → komisyon+kargo ~%40 → ~270 net − ~90 hammadde ≈ 180 TL → %40. Pazaryeri ödeme döngüsü 2–4 hafta → 0 ay
A34: Toptan / fason (firmalara ürün satışı) | B34: 750000 | C34: 0.62 | D34: 0 | E34: Kullanıcı: 500k–1M/ay, çok değişken (orta nokta). Birim 230 TL, hammadde 85–90 TL, etiket yok → (230−87,5)/230 ≈ %62. Tahsilat peşin (kullanıcı)
A35: Doğrudan hammadde satışı | B35: 75000 | C35: 0.3 | D35: 0 | E35: Kullanıcı: 200–250k’lık sipariş, yılda ~4 kez, düzensiz → yıllık ~900k ÷ 12 ≈ 75k/ay. Peşin varsayıldı. Gerçek sipariş aylarını Nakit Akışı 9. satıra elle girebilirsin
A36: Migros (perakende zincir) | B36: 50000 | C36: 0.45 | D36: 2 | E36: Kullanıcı: ~50k/ay, 60 gün vade → 2 ay. Marj verilmedi, %45 varsayıldı (etkisi küçük) — teyit et
A37: Toplam mevcut aylık ciro / ağırlıklı marj | B37: =SUM(B33:B36) -> 1650000 | C37: =IF(B37>0,SUMPRODUCT(B33:B36,C33:C36)/B37,0) -> 0.4969697 | D37: =IF(B37>0,SUMPRODUCT(B33:B36,D33:D36)/B37,0) -> 0.060606061 | E37: Ağırlıklı marj → B5’e link; ağırlıklı vade (ay) bilgi amaçlı
A39: Kredi parametreleri — Vakıfbank Tam Çıpa 6501234486 (değişken faizli, taksitleri bankada boş)
A40: Aylık faiz oranı (TCMB politika faizi + %4,5) / 12 | B40: 0.0345833 | E40: Bankanın 21.08.2026 taksitinde uyguladığı oran. TCMB indirirse güncelle → taksit ve faiz otomatik düşer
A41: BSMV oranı | B41: 0.05 | E41: Faiz üzerinden
A42: Kalan anapara (25.08.2026) | B42: 1106537.6 | E42: Kaynak: Vakıfbank ödeme planı, 15. taksit sonrası bakiye
A43: Kalan taksit sayısı (16–36, Eyl 2026 – May 2028) | B43: 21 | E43: Kaynak: Vakıfbank ödeme planı
A44: Projeksiyon taksiti (eşit taksit, faiz + BSMV dahil) | B44: =PMT(B40*(1+B41),B43,-B42) -> 76218.797 | E44: Bankanın son tahsil ettiği taksit 76.264,16 TL; ~50 TL fark gün sayımından. Kredi Takvimi bu değeri kullanır

Sheet Kredi Takvimi
A1: KONSOLİDE KREDİ ÖDEME TAKVİMİ — Ağu 2026 → Ağu 2029 (TL)
C2: 1. Vakıf Tam Çıpa 1,5M | G2: 2. Vakıf Kadın İst. 1,5M | J2: 3. QNB 1,5M | M2: 4. Vakıf Tam Esnaf 500k | P2: 5. Vakıf Tam Esnaf 400k | S2: 6. Vakıf Trendyol 385k | V2: 7. Vakıf SKY KOBİ 100k
A3: Ay | B3: Yıl | C3: Taksit | D3: Faiz+BSMV | E3: Anapara | F3: Kalan bakiye | G3: Taksit | H3: Faiz+BSMV | I3: Anapara | J3: Taksit | K3: Faiz+BSMV | L3: Anapara | M3: Taksit | N3: Faiz+BSMV | O3: Anapara | P3: Taksit | Q3: Faiz+BSMV | R3: Anapara | S3: Taksit | T3: Faiz+BSMV | U3: Anapara | V3: Taksit | W3: Faiz+BSMV | X3: Anapara | Y3: TOPLAM TAKSİT | Z3: TOPLAM FAİZ+BSMV | AA3: TOPLAM ANAPARA | AB3: KALAN TOPLAM ANAPARA
A4: Ağu 2026 | B4: 2026 | C4: 0 | D4: 0 | E4: 0 | F4: =Varsayımlar!$B$42 -> 1106537.6 | G4: 0 | H4: 0 | I4: 0 | J4: 0 | K4: 0 | L4: 0 | M4: 41163.97 | N4: 30854.98 | O4: 10308.99 | P4: 0 | Q4: 0 | R4: 0 | S4: 0 | T4: 0 | U4: 0 | V4: 0 | W4: 0 | X4: 0 | Y4: =C4+G4+J4+M4+P4+S4+V4 -> 41163.97 | Z4: =D4+H4+K4+N4+Q4+T4+W4 -> 30854.98 | AA4: =E4+I4+L4+O4+R4+U4+X4 -> 10308.99 | AB4: =AA41-AA4 -> 5643037.6
A5: Eyl 2026 | B5: 2026 | C5: =D5+E5 -> 76218.797 | D5: =Varsayımlar!$B$42*Varsayımlar!$B$40*(1+Varsayımlar!$B$41) -> 40181.109 | E5: =MIN(Varsayımlar!$B$42,Varsayımlar!$B$44-D5) -> 36037.689 | F5: =Varsayımlar!$B$42-E5 -> 1070499.9 | G5: 73554.73 | H5: 51975 | I5: 21579.73 | J5: 77234.02 | K5: 57119.99 | L5: 20114.03 | M5: 41163.97 | N5: 30426.51 | O5: 10737.46 | P5: 21808.66 | Q5: 14078.01 | R5: 7730.65 | S5: 25240.08 | T5: 14065.87 | U5: 11174.21 | V5: 10558.15 | W5: 1379.26 | X5: 9178.89 | Y5: =C5+G5+J5+M5+P5+S5+V5 -> 325778.41 | Z5: =D5+H5+K5+N5+Q5+T5+W5 -> 209225.75 | AA5: =E5+I5+L5+O5+R5+U5+X5 -> 116552.66 | AB5: =AB4-AA5 -> 5526484.9
A6: Eki 2026 | B6: 2026 | C6: =D6+E6 -> 76218.797 | D6: =F5*Varsayımlar!$B$40*(1+Varsayımlar!$B$41) -> 38872.491 | E6: =MIN(F5,Varsayımlar!$B$44-D6) -> 37346.306 | F6: =F5-E6 -> 1033153.6 | G6: 73554.73 | H6: 51227.26 | I6: 22327.47 | J6: 77234.02 | K6: 56354.05 | L6: 20879.97 | M6: 41163.97 | N6: 29980.24 | O6: 11183.73 | P6: 21808.66 | Q6: 13806.09 | R6: 8002.57 | S6: 25240.08 | T6: 14106.22 | U6: 11133.86 | V6: 10558.15 | W6: 1126 | X6: 9432.15 | Y6: =C6+G6+J6+M6+P6+S6+V6 -> 325778.41 | Z6: =D6+H6+K6+N6+Q6+T6+W6 -> 205472.35 | AA6: =E6+I6+L6+O6+R6+U6+X6 -> 120306.06 | AB6: =AB5-AA6 -> 5406178.9
A7: Kas 2026 | B7: 2026 | C7: =D7+E7 -> 76218.797 | D7: =F6*Varsayımlar!$B$40*(1+Varsayımlar!$B$41) -> 37516.355 | E7: =MIN(F6,Varsayımlar!$B$44-D7) -> 38702.443 | F7: =F6-E7 -> 994451.18 | G7: 73554.73 | H7: 50453.61 | I7: 23101.12 | J7: 77234.02 | K7: 55558.93 | L7: 21675.09 | M7: 41163.97 | N7: 29515.42 | O7: 11648.55 | P7: 21808.66 | Q7: 13524.6 | R7: 8284.06 | S7: 25240.08 | T7: 13663.15 | U7: 11576.93 | V7: 10558.15 | W7: 790.92 | X7: 9767.23 | Y7: =C7+G7+J7+M7+P7+S7+V7 -> 325778.41 | Z7: =D7+H7+K7+N7+Q7+T7+W7 -> 201022.98 | AA7: =E7+I7+L7+O7+R7+U7+X7 -> 124755.42 | AB7: =AB6-AA7 -> 5281423.4
A8: Ara 2026 | B8: 2026 | C8: =D8+E8 -> 76218.797 | D8: =F7*Varsayımlar!$B$40*(1+Varsayımlar!$B$41) -> 36110.974 | E8: =MIN(F7,Varsayımlar!$B$44-D8) -> 40107.824 | F8: =F7-E8 -> 954343.36 | G8: 73554.73 | H8: 49653.17 | I8: 23901.56 | J8: 77234.02 | K8: 54733.55 | L8: 22500.47 | M8: 41163.97 | N8: 29031.27 | O8: 12132.7 | P8: 21808.66 | Q8: 13233.2 | R8: 8575.46 | S8: 25240.08 | T8: 13202.45 | U8: 12037.63 | V8: 10558.08 | W8: 377.18 | X8: 10180.9 | Y8: =C8+G8+J8+M8+P8+S8+V8 -> 325778.34 | Z8: =D8+H8+K8+N8+Q8+T8+W8 -> 196341.79 | AA8: =E8+I8+L8+O8+R8+U8+X8 -> 129436.54 | AB8: =AB7-AA8 -> 5151986.9
A9: Oca 2027 | B9: 2027 | C9: =D9+E9 -> 76218.797 | D9: =F8*Varsayımlar!$B$40*(1+Varsayımlar!$B$41) -> 34654.56 | E9: =MIN(F8,Varsayımlar!$B$44-D9) -> 41564.238 | F9: =F8-E9 -> 912779.12 | G9: 73554.73 | H9: 48824.97 | I9: 24729.76 | J9: 77234.02 | K9: 53876.73 | L9: 23357.29 | M9: 41163.97 | N9: 28527.01 | O9: 12636.96 | P9: 21808.66 | Q9: 12931.57 | R9: 8877.09 | S9: 25240.08 | T9: 13603.78 | U9: 11636.3 | V9: 0 | W9: 0 | X9: 0 | Y9: =C9+G9+J9+M9+P9+S9+V9 -> 315220.26 | Z9: =D9+H9+K9+N9+Q9+T9+W9 -> 192418.62 | AA9: =E9+I9+L9+O9+R9+U9+X9 -> 122801.64 | AB9: =AB8-AA9 -> 5029185.3
A10: Şub 2027 | B10: 2027 | C10: =D10+E10 -> 76218.797 | D10: =F9*Varsayımlar!$B$40*(1+Varsayımlar!$B$41) -> 33145.26 | E10: =MIN(F9,Varsayımlar!$B$44-D10) -> 43073.537 | F10: =F9-E10 -> 869705.58 | G10: 73554.73 | H10: 47968.08 | I10: 25586.65 | J10: 77234.02 | K10: 52987.28 | L10: 24246.74 | M10: 41163.97 | N10: 28001.79 | O10: 13162.18 | P10: 21808.66 | Q10: 12619.31 | R10: 9189.35 | S10: 25240.08 | T10: 11442.98 | U10: 13797.1 | V10: 0 | W10: 0 | X10: 0 | Y10: =C10+G10+J10+M10+P10+S10+V10 -> 315220.26 | Z10: =D10+H10+K10+N10+Q10+T10+W10 -> 186164.7 | AA10: =E10+I10+L10+O10+R10+U10+X10 -> 129055.56 | AB10: =AB9-AA10 -> 4900129.7
A11: Mar 2027 | B11: 2027 | C11: =D11+E11 -> 76218.797 | D11: =F10*Varsayımlar!$B$40*(1+Varsayımlar!$B$41) -> 31581.154 | E11: =MIN(F10,Varsayımlar!$B$44-D11) -> 44637.644 | F11: =F10-E11 -> 825067.94 | G11: 73554.73 | H11: 47081.51 | I11: 26473.22 | J11: 77234.02 | K11: 52063.98 | L11: 25170.04 | M11: 41163.97 | N11: 27454.73 | O11: 13709.24 | P11: 21808.66 | Q11: 12296.08 | R11: 9512.58 | S11: 25240.08 | T11: 11711.29 | U11: 13528.79 | V11: 0 | W11: 0 | X11: 0 | Y11: =C11+G11+J11+M11+P11+S11+V11 -> 315220.26 | Z11: =D11+H11+K11+N11+Q11+T11+W11 -> 182188.74 | AA11: =E11+I11+L11+O11+R11+U11+X11 -> 133031.51 | AB11: =AB10-AA11 -> 4767098.2
A12: Nis 2027 | B12: 2027 | C12: =D12+E12 -> 76218.797 | D12: =F11*Varsayımlar!$B$40*(1+Varsayımlar!$B$41) -> 29960.251 | E12: =MIN(F11,Varsayımlar!$B$44-D12) -> 46258.547 | F12: =F11-E12 -> 778809.39 | G12: 73554.73 | H12: 46164.22 | I12: 27390.51 | J12: 77234.02 | K12: 51105.5 | L12: 26128.52 | M12: 41163.97 | N12: 26884.94 | O12: 14279.03 | P12: 21808.66 | Q12: 11961.47 | R12: 9847.19 | S12: 25240.08 | T12: 12332.54 | U12: 12907.54 | V12: 0 | W12: 0 | X12: 0 | Y12: =C12+G12+J12+M12+P12+S12+V12 -> 315220.26 | Z12: =D12+H12+K12+N12+Q12+T12+W12 -> 178408.92 | AA12: =E12+I12+L12+O12+R12+U12+X12 -> 136811.34 | AB12: =AB11-AA12 -> 4630286.9
A13: May 2027 | B13: 2027 | C13: =D13+E13 -> 76218.797 | D13: =F12*Varsayımlar!$B$40*(1+Varsayımlar!$B$41) -> 28280.489 | E13: =MIN(F12,Varsayımlar!$B$44-D13) -> 47938.309 | F13: =F12-E13 -> 730871.08 | G13: 73554.73 | H13: 45215.13 | I13: 28339.6 | J13: 77234.02 | K13: 50110.53 | L13: 27123.49 | M13: 41163.97 | N13: 26291.46 | O13: 14872.51 | P13: 21808.66 | Q13: 11615.1 | R13: 10193.56 | S13: 25240.08 | T13: 9948.63 | U13: 15291.45 | V13: 0 | W13: 0 | X13: 0 | Y13: =C13+G13+J13+M13+P13+S13+V13 -> 315220.26 | Z13: =D13+H13+K13+N13+Q13+T13+W13 -> 171461.34 | AA13: =E13+I13+L13+O13+R13+U13+X13 -> 143758.92 | AB13: =AB12-AA13 -> 4486527.9
A14: Haz 2027 | B14: 2027 | C14: =D14+E14 -> 76218.797 | D14: =F13*Varsayımlar!$B$40*(1+Varsayımlar!$B$41) -> 26539.731 | E14: =MIN(F13,Varsayımlar!$B$44-D14) -> 49679.067 | F14: =F13-E14 -> 681192.02 | G14: 73554.73 | H14: 44233.16 | I14: 29321.57 | J14: 77234.02 | K14: 49077.66 | L14: 28156.36 | M14: 41163.97 | N14: 25673.33 | O14: 15490.64 | P14: 21808.66 | Q14: 11256.54 | R14: 10552.12 | S14: 25240.08 | T14: 9715.7 | U14: 15524.38 | V14: 0 | W14: 0 | X14: 0 | Y14: =C14+G14+J14+M14+P14+S14+V14 -> 315220.26 | Z14: =D14+H14+K14+N14+Q14+T14+W14 -> 166496.12 | AA14: =E14+I14+L14+O14+R14+U14+X14 -> 148724.14 | AB14: =AB13-AA14 -> 4337803.8
A15: Tem 2027 | B15: 2027 | C15: =D15+E15 -> 76218.797 | D15: =F14*Varsayımlar!$B$40*(1+Varsayımlar!$B$41) -> 24735.761 | E15: =MIN(F14,Varsayımlar!$B$44-D15) -> 51483.036 | F15: =F14-E15 -> 629708.98 | G15: 73554.73 | H15: 43217.17 | I15: 30337.56 | J15: 77234.02 | K15: 48005.46 | L15: 29228.56 | M15: 41163.97 | N15: 25029.5 | O15: 16134.47 | P15: 21808.66 | Q15: 10885.37 | R15: 10923.29 | S15: 25240.08 | T15: 9432.94 | U15: 15807.14 | V15: 0 | W15: 0 | X15: 0 | Y15: =C15+G15+J15+M15+P15+S15+V15 -> 315220.26 | Z15: =D15+H15+K15+N15+Q15+T15+W15 -> 161306.2 | AA15: =E15+I15+L15+O15+R15+U15+X15 -> 153914.06 | AB15: =AB14-AA15 -> 4183889.7
A16: Ağu 2027 | B16: 2027 | C16: =D16+E16 -> 76218.797 | D16: =F15*Varsayımlar!$B$40*(1+Varsayımlar!$B$41) -> 22866.285 | E16: =MIN(F15,Varsayımlar!$B$44-D16) -> 53352.512 | F16: =F15-E16 -> 576356.47 | G16: 73554.73 | H16: 42165.97 | I16: 31388.76 | J16: 77234.02 | K16: 46892.44 | L16: 30341.58 | M16: 41163.97 | N16: 24358.91 | O16: 16805.06 | P16: 21808.66 | Q16: 10501.14 | R16: 11307.52 | S16: 25240.08 | T16: 8803.89 | U16: 16436.19 | V16: 0 | W16: 0 | X16: 0 | Y16: =C16+G16+J16+M16+P16+S16+V16 -> 315220.26 | Z16: =D16+H16+K16+N16+Q16+T16+W16 -> 155588.64 | AA16: =E16+I16+L16+O16+R16+U16+X16 -> 159631.62 | AB16: =AB15-AA16 -> 4024258.1
A17: Eyl 2027 | B17: 2027 | C17: =D17+E17 -> 76218.797 | D17: =F16*Varsayımlar!$B$40*(1+Varsayımlar!$B$41) -> 20928.924 | E17: =MIN(F16,Varsayımlar!$B$44-D17) -> 55289.873 | F17: =F16-E17 -> 521066.6 | G17: 73554.73 | H17: 41078.35 | I17: 32476.38 | J17: 77234.02 | K17: 45737.03 | L17: 31496.99 | M17: 41163.97 | N17: 23660.45 | O17: 17503.52 | P17: 21808.66 | Q17: 10103.4 | R17: 11705.26 | S17: 25240.08 | T17: 8149.82 | U17: 17090.26 | V17: 0 | W17: 0 | X17: 0 | Y17: =C17+G17+J17+M17+P17+S17+V17 -> 315220.26 | Z17: =D17+H17+K17+N17+Q17+T17+W17 -> 149657.97 | AA17: =E17+I17+L17+O17+R17+U17+X17 -> 165562.28 | AB17: =AB16-AA17 -> 3858695.8
... A24: Nis 2028 | B24: 2028 | C24: =D24+E24 -> 76218.797 | D24: =F23*Varsayımlar!$B$40*(1+Varsayımlar!$B$41) -> 5247.8426 | E24: =MIN(F23,Varsayımlar!$B$44-D24) -> 70970.955 | F24: =F23-E24 -> 73548.085 | G24: 73554.73 | H24: 32333.42 | I24: 41221.31 | J24: 77234.02 | K24: 36318.82 | L24: 40915.2 | M24: 41163.97 | N24: 17887.2 | O24: 23276.77 | P24: 21808.66 | Q24: 6898.67 | R24: 14909.99 | S24: 25240.08 | T24: 2883.52 | U24: 22356.56 | V24: 0 | W24: 0 | X24: 0 | Y24: =C24+G24+J24+M24+P24+S24+V24 -> 315220.26 | Z24: =D24+H24+K24+N24+Q24+T24+W24 -> 101569.47 | AA24: =E24+I24+L24+O24+R24+U24+X24 -> 213650.78 | AB24: =AB23-AA24 -> 2514291.4
A25: May 2028 | B25: 2028 | C25: =D25+E25 -> 76218.797 | D25: =F24*Varsayımlar!$B$40*(1+Varsayımlar!$B$41) -> 2670.7123 | E25: =F24 -> 73548.085 | F25: =F24-E25 -> 0 | G25: 73554.73 | H25: 30905.1 | I25: 42649.63 | J25: 77234.02 | K25: 34760.76 | L25: 42473.26 | M25: 41163.97 | N25: 16919.76 | O25: 24244.21 | P25: 21808.66 | Q25: 6374.2 | R25: 15434.46 | S25: 25240.08 | T25: 1834.17 | U25: 23405.91 | V25: 0 | W25: 0 | X25: 0 | Y25: =C25+G25+J25+M25+P25+S25+V25 -> 315220.26 | Z25: =D25+H25+K25+N25+Q25+T25+W25 -> 93464.702 | AA25: =E25+I25+L25+O25+R25+U25+X25 -> 221755.56 | AB25: =AB24-AA25 -> 2292535.8
A26: Haz 2028 | B26: 2028 | C26: 0 | D26: 0 | E26: 0 | F26: 0 | G26: 73554.73 | H26: 29427.29 | I26: 44127.44 | J26: 77234.02 | K26: 33143.39 | L26: 44090.63 | M26: 41163.97 | N26: 15912.11 | O26: 25251.86 | P26: 21808.66 | Q26: 5831.3 | R26: 15977.36 | S26: 25239.78 | T26: 965.98 | U26: 24273.8 | V26: 0 | W26: 0 | X26: 0 | Y26: =C26+G26+J26+M26+P26+S26+V26 -> 239001.16 | Z26: =D26+H26+K26+N26+Q26+T26+W26 -> 85280.07 | AA26: =E26+I26+L26+O26+R26+U26+X26 -> 153721.09 | AB26: =AB25-AA26 -> 2138814.7
A27: Tem 2028 | B27: 2028 | C27: 0 | D27: 0 | E27: 0 | F27: 0 | G27: 73554.73 | H27: 27898.28 | I27: 45656.45 | J27: 77234.02 | K27: 31464.42 | L27: 45769.6 | M27: 41163.97 | N27: 14862.58 | O27: 26301.39 | P27: 21808.66 | Q27: 5269.3 | R27: 16539.36 | S27: 0 | T27: 0 | U27: 0 | V27: 0 | W27: 0 | X27: 0 | Y27: =C27+G27+J27+M27+P27+S27+V27 -> 213761.38 | Z27: =D27+H27+K27+N27+Q27+T27+W27 -> 79494.58 | AA27: =E27+I27+L27+O27+R27+U27+X27 -> 134266.8 | AB27: =AB26-AA27 -> 2004547.9
A28: Ağu 2028 | B28: 2028 | C28: 0 | D28: 0 | E28: 0 | F28: 0 | G28: 73554.73 | H28: 26316.28 | I28: 47238.45 | J28: 77234.02 | K28: 29721.51 | L28: 47512.51 | M28: 41163.97 | N28: 13769.43 | O28: 27394.54 | P28: 21808.66 | Q28: 4687.53 | R28: 17121.13 | S28: 0 | T28: 0 | U28: 0 | V28: 0 | W28: 0 | X28: 0 | Y28: =C28+G28+J28+M28+P28+S28+V28 -> 213761.38 | Z28: =D28+H28+K28+N28+Q28+T28+W28 -> 74494.75 | AA28: =E28+I28+L28+O28+R28+U28+X28 -> 139266.63 | AB28: =AB27-AA28 -> 1865281.3
A29: Eyl 2028 | B29: 2028 | C29: 0 | D29: 0 | E29: 0 | F29: 0 | G29: 73554.73 | H29: 24679.46 | I29: 48875.27 | J29: 77234.02 | K29: 27912.23 | L29: 49321.79 | M29: 41163.97 | N29: 12630.84 | O29: 28533.13 | P29: 21808.66 | Q29: 4085.29 | R29: 17723.37 | S29: 0 | T29: 0 | U29: 0 | V29: 0 | W29: 0 | X29: 0 | Y29: =C29+G29+J29+M29+P29+S29+V29 -> 213761.38 | Z29: =D29+H29+K29+N29+Q29+T29+W29 -> 69307.82 | AA29: =E29+I29+L29+O29+R29+U29+X29 -> 144453.56 | AB29: =AB28-AA29 -> 1720827.7
A30: Eki 2028 | B30: 2028 | C30: 0 | D30: 0 | E30: 0 | F30: 0 | G30: 73554.73 | H30: 22985.94 | I30: 50568.79 | J30: 77234.02 | K30: 26034.06 | L30: 51199.96 | M30: 41163.97 | N30: 11444.94 | O30: 29719.03 | P30: 21808.66 | Q30: 3461.87 | R30: 18346.79 | S30: 0 | T30: 0 | U30: 0 | V30: 0 | W30: 0 | X30: 0 | Y30: =C30+G30+J30+M30+P30+S30+V30 -> 213761.38 | Z30: =D30+H30+K30+N30+Q30+T30+W30 -> 63926.81 | AA30: =E30+I30+L30+O30+R30+U30+X30 -> 149834.57 | AB30: =AB29-AA30 -> 1570993.1
A31: Kas 2028 | B31: 2028 | C31: 0 | D31: 0 | E31: 0 | F31: 0 | G31: 73554.73 | H31: 21233.73 | I31: 52321 | J31: 77234.02 | K31: 24084.36 | L31: 53149.66 | M31: 41163.97 | N31: 10209.74 | O31: 30954.23 | P31: 21808.66 | Q31: 2816.52 | R31: 18992.14 | S31: 0 | T31: 0 | U31: 0 | V31: 0 | W31: 0 | X31: 0 | Y31: =C31+G31+J31+M31+P31+S31+V31 -> 213761.38 | Z31: =D31+H31+K31+N31+Q31+T31+W31 -> 58344.35 | AA31: =E31+I31+L31+O31+R31+U31+X31 -> 155417.03 | AB31: =AB30-AA31 -> 1415576.1
A32: Ara 2028 | B32: 2028 | C32: 0 | D32: 0 | E32: 0 | F32: 0 | G32: 73554.73 | H32: 19420.81 | I32: 54133.92 | J32: 77234.02 | K32: 22060.43 | L32: 55173.59 | M32: 41163.97 | N32: 8923.2 | O32: 32240.77 | P32: 21808.66 | Q32: 2148.47 | R32: 19660.19 | S32: 0 | T32: 0 | U32: 0 | V32: 0 | W32: 0 | X32: 0 | Y32: =C32+G32+J32+M32+P32+S32+V32 -> 213761.38 | Z32: =D32+H32+K32+N32+Q32+T32+W32 -> 52552.91 | AA32: =E32+I32+L32+O32+R32+U32+X32 -> 161208.47 | AB32: =AB31-AA32 -> 1254367.6
A33: Oca 2029 | B33: 2029 | C33: 0 | D33: 0 | E33: 0 | F33: 0 | G33: 73554.73 | H33: 17545.07 | I33: 56009.66 | J33: 77234.02 | K33: 19959.42 | L33: 57274.6 | M33: 41163.97 | N33: 7583.19 | O33: 33580.78 | P33: 21808.66 | Q33: 1456.93 | R33: 20351.73 | S33: 0 | T33: 0 | U33: 0 | V33: 0 | W33: 0 | X33: 0 | Y33: =C33+G33+J33+M33+P33+S33+V33 -> 213761.38 | Z33: =D33+H33+K33+N33+Q33+T33+W33 -> 46544.61 | AA33: =E33+I33+L33+O33+R33+U33+X33 -> 167216.77 | AB33: =AB32-AA33 -> 1087150.9
A34: Şub 2029 | B34: 2029 | C34: 0 | D34: 0 | E34: 0 | F34: 0 | G34: 73554.73 | H34: 15604.33 | I34: 57950.4 | J34: 77234.02 | K34: 17778.4 | L34: 59455.62 | M34: 41163.97 | N34: 6187.49 | O34: 34976.48 | P34: 21808.64 | Q34: 741.05 | R34: 21067.59 | S34: 0 | T34: 0 | U34: 0 | V34: 0 | W34: 0 | X34: 0 | Y34: =C34+G34+J34+M34+P34+S34+V34 -> 213761.36 | Z34: =D34+H34+K34+N34+Q34+T34+W34 -> 40311.27 | AA34: =E34+I34+L34+O34+R34+U34+X34 -> 173450.09 | AB34: =AB33-AA34 -> 913700.79
A35: Mar 2029 | B35: 2029 | C35: 0 | D35: 0 | E35: 0 | F35: 0 | G35: 73554.73 | H35: 13596.36 | I35: 59958.37 | J35: 77234.02 | K35: 15514.33 | L35: 61719.69 | M35: 41163.97 | N35: 4733.78 | O35: 36430.19 | P35: 0 | Q35: 0 | R35: 0 | S35: 0 | T35: 0 | U35: 0 | V35: 0 | W35: 0 | X35: 0 | Y35: =C35+G35+J35+M35+P35+S35+V35 -> 191952.72 | Z35: =D35+H35+K35+N35+Q35+T35+W35 -> 33844.47 | AA35: =E35+I35+L35+O35+R35+U35+X35 -> 158108.25 | AB35: =AB34-AA35 -> 755592.54
A36: Nis 2029 | B36: 2029 | C36: 0 | D36: 0 | E36: 0 | F36: 0 | G36: 73554.73 | H36: 11518.79 | I36: 62035.94 | J36: 77234.02 | K36: 13164.04 | L36: 64069.98 | M36: 41163.97 | N36: 3219.66 | O36: 37944.31 | P36: 0 | Q36: 0 | R36: 0 | S36: 0 | T36: 0 | U36: 0 | V36: 0 | W36: 0 | X36: 0 | Y36: =C36+G36+J36+M36+P36+S36+V36 -> 191952.72 | Z36: =D36+H36+K36+N36+Q36+T36+W36 -> 27902.49 | AA36: =E36+I36+L36+O36+R36+U36+X36 -> 164050.23 | AB36: =AB35-AA36 -> 591542.31
A37: May 2029 | B37: 2029 | C37: 0 | D37: 0 | E37: 0 | F37: 0 | G37: 73554.73 | H37: 9369.24 | I37: 64185.49 | J37: 77234.02 | K37: 10724.26 | L37: 66509.76 | M37: 41163.59 | N37: 1642.59 | O37: 39521 | P37: 0 | Q37: 0 | R37: 0 | S37: 0 | T37: 0 | U37: 0 | V37: 0 | W37: 0 | X37: 0 | Y37: =C37+G37+J37+M37+P37+S37+V37 -> 191952.34 | Z37: =D37+H37+K37+N37+Q37+T37+W37 -> 21736.09 | AA37: =E37+I37+L37+O37+R37+U37+X37 -> 170216.25 | AB37: =AB36-AA37 -> 421326.06
... A40: Ağu 2029 | B40: 2029 | C40: 0 | D40: 0 | E40: 0 | F40: 0 | G40: 73554.51 | H40: 2463.31 | I40: 71091.2 | J40: 77233.87 | K40: 2833.17 | L40: 74400.7 | M40: 0 | N40: 0 | O40: 0 | P40: 0 | Q40: 0 | R40: 0 | S40: 0 | T40: 0 | U40: 0 | V40: 0 | W40: 0 | X40: 0 | Y40: =C40+G40+J40+M40+P40+S40+V40 -> 150788.38 | Z40: =D40+H40+K40+N40+Q40+T40+W40 -> 5296.48 | AA40: =E40+I40+L40+O40+R40+U40+X40 -> 145491.9 | AB40: =AB39-AA40 -> 6.693881e-10
A41: TOPLAM | C41: =SUM(C4:C40) -> 1600594.7 | D41: =SUM(D4:D40) -> 494057.12 | E41: =SUM(E4:E40) -> 1106537.6 | G41: =SUM(G4:G40) -> 2647970.1 | H41: =SUM(H4:H40) -> 1147970.1 | I41: =SUM(I4:I40) -> 1500000 | J41: =SUM(J4:J40) -> 2780424.6 | K41: =SUM(K4:K40) -> 1280424.6 | L41: =SUM(L4:L40) -> 1500000 | M41: =SUM(M4:M40) -> 1399574.6 | N41: =SUM(N4:N40) -> 657199.09 | ... AA41: =SUM(AA4:AA40) -> 5653346.6 | AB41: Başlangıç bakiyesi → sütun başı
A43: Mavi = banka ödeme planından alınan rakamlar (Vakıfbank 25.08.2026, QNB valör 11.08.2026). Tam Çıpa kredisi (değişken faiz) Varsayımlar sayfasındaki oranla formülle hesaplanır.

Sheet Krediler
A1: KREDİ PORTFÖYÜ ÖZETİ — Bigetaş Biyoteknoloji A.Ş. (25.08.2026 itibarıyla)
A2: Kaynak: Vakıfbank Tire Şb. ticari kredi ödeme planları (6 adet) ve QNB Bank Ödemiş Şb. ödeme planı (1 adet). Kalan tutarlar Kredi Takvimi sayfasından formülle gelir.
A4: # | B4: Banka | C4: Ürün | D4: Hesap / Referans | E4: Kredi tutarı | F4: Açılış | G4: Vade (ay) | H4: Aylık faiz % | I4: Faiz tipi | J4: Aylık taksit | K4: Kalan taksit | L4: İlk kalan taksit | M4: Son taksit | N4: Kalan anapara | O4: Kalan toplam ödeme | P4: Kalan faiz+BSMV | Q4: Ödeme günü
A5: 1 | B5: Vakıfbank | C5: Tam Çıpa Kredisi (değişken faiz: TCMB politika faizi + 4,5) | D5: 6501234486 | E5: 1500000 | F5: 21.05.2025 | G5: 36 | H5: 0.0345833 | I5: Değişken | J5: =MAX('Kredi Takvimi'!C4:C40) -> 76218.797 | K5: =COUNTIF('Kredi Takvimi'!C4:C40,">0") -> 21 | L5: 21.09.2026 | M5: 22.05.2028 | N5: =SUM('Kredi Takvimi'!E4:E40) -> 1106537.6 | O5: =SUM('Kredi Takvimi'!C4:C40) -> 1600594.7 | P5: =SUM('Kredi Takvimi'!D4:D40) -> 494057.12 | Q5: 21
A6: 2 | B6: Vakıfbank | C6: Kadın İstihdamı Güçlendirme Kredisi | D6: 6501643201 | E6: 1500000 | F6: 05.08.2026 | G6: 36 | H6: 0.033 | I6: Sabit | J6: =MAX('Kredi Takvimi'!G4:G40) -> 73554.73 | K6: =COUNTIF('Kredi Takvimi'!G4:G40,">0") -> 36 | L6: 05.09.2026 | M6: 05.08.2029 | N6: =SUM('Kredi Takvimi'!I4:I40) -> 1500000 | O6: =SUM('Kredi Takvimi'!G4:G40) -> 2647970.1 | P6: =SUM('Kredi Takvimi'!H4:H40) -> 1147970.1 | Q6: 5
A7: 3 | B7: QNB Bank | C7: Taksitli Ticari Kredi (Ödemiş Şb.) | D7: 01421-TT-000000022018 | E7: 1500000 | F7: 11.08.2026 | G7: 36 | H7: 0.0363 | I7: Sabit | J7: =MAX('Kredi Takvimi'!J4:J40) -> 77234.02 | K7: =COUNTIF('Kredi Takvimi'!J4:J40,">0") -> 36 | L7: 11.09.2026 | M7: 11.08.2029 | N7: =SUM('Kredi Takvimi'!L4:L40) -> 1500000 | O7: =SUM('Kredi Takvimi'!J4:J40) -> 2780424.6 | P7: =SUM('Kredi Takvimi'!K4:K40) -> 1280424.6 | Q7: 11
A8: 4 | B8: Vakıfbank | C8: Tam Esnaf Standart Kredi — 500.000 TL (12 ay ödemesiz) | D8: 6501216448 | E8: 500000 | F8: 29.04.2025 | G8: 49 | H8: 0.0395833 | I8: Sabit | J8: =MAX('Kredi Takvimi'!M4:M40) -> 41163.97 | K8: =COUNTIF('Kredi Takvimi'!M4:M40,">0") -> 34 | L8: 29.08.2026 | M8: 29.05.2029 | N8: =SUM('Kredi Takvimi'!O4:O40) -> 742375.51 | O8: =SUM('Kredi Takvimi'!M4:M40) -> 1399574.6 | P8: =SUM('Kredi Takvimi'!N4:N40) -> 657199.09 | Q8: 29
A9: 5 | B9: Vakıfbank | C9: Tam Esnaf Standart Kredi — 400.000 TL (3 ay ödemesiz) | D9: 6501493908 | E9: 400000 | F9: 05.02.2026 | G9: 36 | H9: 0.0335 | I9: Sabit | J9: =MAX('Kredi Takvimi'!P4:P40) -> 21808.66 | K9: =COUNTIF('Kredi Takvimi'!P4:P40,">0") -> 30 | L9: 05.09.2026 | M9: 05.02.2029 | N9: =SUM('Kredi Takvimi'!R4:R40) -> 400227.86 | O9: =SUM('Kredi Takvimi'!P4:P40) -> 654259.78 | P9: =SUM('Kredi Takvimi'!Q4:Q40) -> 254031.92 | Q9: 5
A10: 6 | B10: Vakıfbank | C10: Trendyol Dijital İşletme İhtiyaç Kredisi | D10: 6501603873 | E10: 385000 | F10: 05.06.2026 | G10: 24 | H10: 0.0379 | I10: Sabit | J10: =MAX('Kredi Takvimi'!S4:S40) -> 25240.08 | K10: =COUNTIF('Kredi Takvimi'!S4:S40,">0") -> 22 | L10: 23.09.2026 | M10: 23.06.2028 | N10: =SUM('Kredi Takvimi'!U4:U40) -> 365646.41 | O10: =SUM('Kredi Takvimi'!S4:S40) -> 555281.46 | P10: =SUM('Kredi Takvimi'!T4:T40) -> 189635.05 | Q10: 23
A11: 7 | B11: Vakıfbank | C11: SKY KOBİ Dijital Kredi | D11: 6501452442 | E11: 100000 | F11: 22.12.2025 | G11: 12 | H11: 0.0365 | I11: Sabit | J11: =MAX('Kredi Takvimi'!V4:V40) -> 10558.15 | K11: =COUNTIF('Kredi Takvimi'!V4:V40,">0") -> 4 | L11: 22.09.2026 | M11: 22.12.2026 | N11: =SUM('Kredi Takvimi'!X4:X40) -> 38559.17 | O11: =SUM('Kredi Takvimi'!V4:V40) -> 42232.53 | P11: =SUM('Kredi Takvimi'!W4:W40) -> 3673.36 | Q11: 22
B12: TOPLAM | E12: =SUM(E5:E11) -> 5885000 | N12: =SUM(N5:N11) -> 5653346.6 | O12: =SUM(O5:O11) -> 9680337.7 | P12: =SUM(P5:P11) -> 4026991.2
A14: Notlar
A15: 1) Tam Çıpa kredisi değişken faizli (TCMB politika faizi + %4,5, taban %18). Banka 16–36. taksitleri boş bırakmış; projeksiyon Varsayımlar sayfasındaki faiz oranıyla hesaplanır. TCMB indirdikçe taksit düşer.
A16: 2) Kalan anapara ve ödemeler 25.08.2026 itibarıyla; Tam Esnaf 500k kredisinin 29.08.2026 tarihli 41.163,97 TL taksiti henüz ödenmemiş görünüyor ve takvime Ağu 2026 satırında dahil.
A17: 3) Kadın İstihdamı (05.08.2026) ve QNB (11.08.2026) kredileri yeni kullandırım — toplam 3.000.000 TL; ilk taksitleri Eylül 2026.
A18: 4) Trendyol kredisinin 1. taksiti (34.432,72) ve SKY KOBİ 1–8, Tam Çıpa 1–15, Tam Esnaf 400k 1–4, Tam Esnaf 500k 1–4 taksitleri ödenmiş; takvimde yalnız kalan taksitler var.

Sheet Nakit Akışı
A1: AYLIK NAKİT AKIŞI PROJEKSİYONU — Eyl 2026 → Ağu 2029 (TL, KDV hariç ciro / KDV dahil gider)
A2: Ciro = Varsayımlar’daki kanal ciroları × senaryo çarpanı × büyüme. Belirli aylara gerçek rakam yazmak istersen 7–10. satırlara mavi yazıyla gir. Diğer girişler / Yatırım satırları elle girilir.
A4: TL | B4: Eyl 2026 | C4: Eki 2026 | D4: Kas 2026 | E4: Ara 2026 | F4: Oca 2027 | G4: Şub 2027 | H4: Mar 2027 | I4: Nis 2027 | J4: May 2027 | K4: Haz 2027 | L4: Tem 2027 | M4: Ağu 2027 | N4: Eyl 2027 | O4: Eki 2027 | P4: Kas 2027 | Q4: Ara 2027 | R4: Oca 2028 | S4: Şub 2028 | T4: Mar 2028 | U4: Nis 2028 | V4: May 2028 | W4: Haz 2028 | X4: Tem 2028 | Y4: Ağu 2028 | Z4: Eyl 2028 | AA4: Eki 2028 | AB4: Kas 2028 | AC4: Ara 2028 | AD4: Oca 2029 | AE4: Şub 2029 | AF4: Mar 2029 | AG4: Nis 2029 | AH4: May 2029 | AI4: Haz 2029 | AJ4: Tem 2029 | AK4: Ağu 2029 | AL4: 36 AY TOPLAM (oran/hedef satırları: ORT.)
A5: Yıl indeksi (sabit gider artışı için) | B5: =INT((COLUMN()-2)/12) -> 0 | C5: =INT((COLUMN()-2)/12) -> 0 | D5: =INT((COLUMN()-2)/12) -> 0 | E5: =INT((COLUMN()-2)/12) -> 0 | F5: =INT((COLUMN()-2)/12) -> 0 | G5: =INT((COLUMN()-2)/12) -> 0 | H5: =INT((COLUMN()-2)/12) -> 0 | I5: =INT((COLUMN()-2)/12) -> 0 | ... AK5: =INT((COLUMN()-2)/12) -> 2
A7: Ciro — E-ticaret | B7: =Varsayımlar!$B$33*Varsayımlar!$B$9*(1+Varsayımlar!$B$10)^(COLUMN()-2) -> 775000 | C7: =Varsayımlar!$B$33*Varsayımlar!$B$9*(1+Varsayımlar!$B$10)^(COLUMN()-2) -> 775000 | D7: =Varsayımlar!$B$33*Varsayımlar!$B$9*(1+Varsayımlar!$B$10)^(COLUMN()-2) -> 775000 | E7: =Varsayımlar!$B$33*Varsayımlar!$B$9*(1+Varsayımlar!$B$10)^(COLUMN()-2) -> 775000 | F7: =Varsayımlar!$B$33*Varsayımlar!$B$9*(1+Varsayımlar!$B$10)^(COLUMN()-2) -> 775000 | G7: =Varsayımlar!$B$33*Varsayımlar!$B$9*(1+Varsayımlar!$B$10)^(COLUMN()-2) -> 775000 | H7: =Varsayımlar!$B$33*Varsayımlar!$B$9*(1+Varsayımlar!$B$10)^(COLUMN()-2) -> 775000 | I7: =Varsayımlar!$B$33*Varsayımlar!$B$9*(1+Varsayımlar!$B$10)^(COLUMN()-2) -> 775000 | ... AK7: =Varsayımlar!$B$33*Varsayımlar!$B$9*(1+Varsayımlar!$B$10)^(COLUMN()-2) -> 775000 | AL7: =SUM(B7:AK7) -> 27900000
A8: Ciro — Toptan / fason | B8: =Varsayımlar!$B$34*Varsayımlar!$B$9*(1+Varsayımlar!$B$10)^(COLUMN()-2) -> 750000 | C8: =Varsayımlar!$B$34*Varsayımlar!$B$9*(1+Varsayımlar!$B$10)^(COLUMN()-2) -> 750000 | D8: =Varsayımlar!$B$34*Varsayımlar!$B$9*(1+Varsayımlar!$B$10)^(COLUMN()-2) -> 750000 | E8: =Varsayımlar!$B$34*Varsayımlar!$B$9*(1+Varsayımlar!$B$10)^(COLUMN()-2) -> 750000 | F8: =Varsayımlar!$B$34*Varsayımlar!$B$9*(1+Varsayımlar!$B$10)^(COLUMN()-2) -> 750000 | G8: =Varsayımlar!$B$34*Varsayımlar!$B$9*(1+Varsayımlar!$B$10)^(COLUMN()-2) -> 750000 | H8: =Varsayımlar!$B$34*Varsayımlar!$B$9*(1+Varsayımlar!$B$10)^(COLUMN()-2) -> 750000 | I8: =Varsayımlar!$B$34*Varsayımlar!$B$9*(1+Varsayımlar!$B$10)^(COLUMN()-2) -> 750000 | ... AK8: =Varsayımlar!$B$34*Varsayımlar!$B$9*(1+Varsayımlar!$B$10)^(COLUMN()-2) -> 750000 | AL8: =SUM(B8:AK8) -> 27000000
A9: Ciro — Hammadde satışı | B9: =Varsayımlar!$B$35*Varsayımlar!$B$9*(1+Varsayımlar!$B$10)^(COLUMN()-2) -> 75000 | C9: =Varsayımlar!$B$35*Varsayımlar!$B$9*(1+Varsayımlar!$B$10)^(COLUMN()-2) -> 75000 | D9: =Varsayımlar!$B$35*Varsayımlar!$B$9*(1+Varsayımlar!$B$10)^(COLUMN()-2) -> 75000 | E9: =Varsayımlar!$B$35*Varsayımlar!$B$9*(1+Varsayımlar!$B$10)^(COLUMN()-2) -> 75000 | F9: =Varsayımlar!$B$35*Varsayımlar!$B$9*(1+Varsayımlar!$B$10)^(COLUMN()-2) -> 75000 | G9: =Varsayımlar!$B$35*Varsayımlar!$B$9*(1+Varsayımlar!$B$10)^(COLUMN()-2) -> 75000 | H9: =Varsayımlar!$B$35*Varsayımlar!$B$9*(1+Varsayımlar!$B$10)^(COLUMN()-2) -> 75000 | I9: =Varsayımlar!$B$35*Varsayımlar!$B$9*(1+Varsayımlar!$B$10)^(COLUMN()-2) -> 75000 | ... AK9: =Varsayımlar!$B$35*Varsayımlar!$B$9*(1+Varsayımlar!$B$10)^(COLUMN()-2) -> 75000 | AL9: =SUM(B9:AK9) -> 2700000
A10: Ciro — Migros | B10: =Varsayımlar!$B$36*Varsayımlar!$B$9*(1+Varsayımlar!$B$10)^(COLUMN()-2) -> 50000 | C10: =Varsayımlar!$B$36*Varsayımlar!$B$9*(1+Varsayımlar!$B$10)^(COLUMN()-2) -> 50000 | D10: =Varsayımlar!$B$36*Varsayımlar!$B$9*(1+Varsayımlar!$B$10)^(COLUMN()-2) -> 50000 | E10: =Varsayımlar!$B$36*Varsayımlar!$B$9*(1+Varsayımlar!$B$10)^(COLUMN()-2) -> 50000 | F10: =Varsayımlar!$B$36*Varsayımlar!$B$9*(1+Varsayımlar!$B$10)^(COLUMN()-2) -> 50000 | G10: =Varsayımlar!$B$36*Varsayımlar!$B$9*(1+Varsayımlar!$B$10)^(COLUMN()-2) -> 50000 | H10: =Varsayımlar!$B$36*Varsayımlar!$B$9*(1+Varsayımlar!$B$10)^(COLUMN()-2) -> 50000 | I10: =Varsayımlar!$B$36*Varsayımlar!$B$9*(1+Varsayımlar!$B$10)^(COLUMN()-2) -> 50000 | ... AK10: =Varsayımlar!$B$36*Varsayımlar!$B$9*(1+Varsayımlar!$B$10)^(COLUMN()-2) -> 50000 | AL10: =SUM(B10:AK10) -> 1800000
A11: TOPLAM CİRO (KDV hariç) | B11: =SUM(B7:B10) -> 1650000 | C11: =SUM(C7:C10) -> 1650000 | D11: =SUM(D7:D10) -> 1650000 | E11: =SUM(E7:E10) -> 1650000 | F11: =SUM(F7:F10) -> 1650000 | G11: =SUM(G7:G10) -> 1650000 | H11: =SUM(H7:H10) -> 1650000 | I11: =SUM(I7:I10) -> 1650000 | ... AK11: =SUM(AK7:AK10) -> 1650000 | AL11: =SUM(B11:AK11) -> 59400000
A12: Tahsilat (nakit girişi — kanal vadeleriyle) | B12: =INDEX($B$7:$AK$7,1,MAX(1,COLUMN()-2+1-Varsayımlar!$D$33))+INDEX($B$8:$AK$8,1,MAX(1,COLUMN()-2+1-Varsayımlar!$D$34))+INDEX($B$9:$AK$9,1,MAX(1,COLUMN()-2+1-Varsayımlar!$D$35))+INDEX($B$10:$AK$10,1,MAX(1,COLUMN()-2+1-Varsayımlar!$D$36)) -> 1650000 | C12: =INDEX($B$7:$AK$7,1,MAX(1,COLUMN()-2+1-Varsayımlar!$D$33))+INDEX($B$8:$AK$8,1,MAX(1,COLUMN()-2+1-Varsayımlar!$D$34))+INDEX($B$9:$AK$9,1,MAX(1,COLUMN()-2+1-Varsayımlar!$D$35))+INDEX($B$10:$AK$10,1,MAX(1,COLUMN()-2+1-Varsayımlar!$D$36)) -> 1650000 | D12: =INDEX($B$7:$AK$7,1,MAX(1,COLUMN()-2+1-Varsayımlar!$D$33))+INDEX($B$8:$AK$8,1,MAX(1,COLUMN()-2+1-Varsayımlar!$D$34))+INDEX($B$9:$AK$9,1,MAX(1,COLUMN()-2+1-Varsayımlar!$D$35))+INDEX($B$10:$AK$10,1,MAX(1,COLUMN()-2+1-Varsayımlar!$D$36)) -> 1650000 | E12: =INDEX($B$7:$AK$7,1,MAX(1,COLUMN()-2+1-Varsayımlar!$D$33))+INDEX($B$8:$AK$8,1,MAX(1,COLUMN()-2+1-Varsayımlar!$D$34))+INDEX($B$9:$AK$9,1,MAX(1,COLUMN()-2+1-Varsayımlar!$D$35))+INDEX($B$10:$AK$10,1,MAX(1,COLUMN()-2+1-Varsayımlar!$D$36)) -> 1650000 | F12: =INDEX($B$7:$AK$7,1,MAX(1,COLUMN()-2+1-Varsayımlar!$D$33))+INDEX($B$8:$AK$8,1,MAX(1,COLUMN()-2+1-Varsayımlar!$D$34))+INDEX($B$9:$AK$9,1,MAX(1,COLUMN()-2+1-Varsayımlar!$D$35))+INDEX($B$10:$AK$10,1,MAX(1,COLUMN()-2+1-Varsayımlar!$D$36)) -> 1650000 | G12: =INDEX($B$7:$AK$7,1,MAX(1,COLUMN()-2+1-Varsayımlar!$D$33))+INDEX($B$8:$AK$8,1,MAX(1,COLUMN()-2+1-Varsayımlar!$D$34))+INDEX($B$9:$AK$9,1,MAX(1,COLUMN()-2+1-Varsayımlar!$D$35))+INDEX($B$10:$AK$10,1,MAX(1,COLUMN()-2+1-Varsayımlar!$D$36)) -> 1650000 | H12: =INDEX($B$7:$AK$7,1,MAX(1,COLUMN()-2+1-Varsayımlar!$D$33))+INDEX($B$8:$AK$8,1,MAX(1,COLUMN()-2+1-Varsayımlar!$D$34))+INDEX($B$9:$AK$9,1,MAX(1,COLUMN()-2+1-Varsayımlar!$D$35))+INDEX($B$10:$AK$10,1,MAX(1,COLUMN()-2+1-Varsayımlar!$D$36)) -> 1650000 | I12: =INDEX($B$7:$AK$7,1,MAX(1,COLUMN()-2+1-Varsayımlar!$D$33))+INDEX($B$8:$AK$8,1,MAX(1,COLUMN()-2+1-Varsayımlar!$D$34))+INDEX($B$9:$AK$9,1,MAX(1,COLUMN()-2+1-Varsayımlar!$D$35))+INDEX($B$10:$AK$10,1,MAX(1,COLUMN()-2+1-Varsayımlar!$D$36)) -> 1650000 | ... AK12: =INDEX($B$7:$AK$7,1,MAX(1,COLUMN()-2+1-Varsayımlar!$D$33))+INDEX($B$8:$AK$8,1,MAX(1,COLUMN()-2+1-Varsayımlar!$D$34))+INDEX($B$9:$AK$9,1,MAX(1,COLUMN()-2+1-Varsayımlar!$D$35))+INDEX($B$10:$AK$10,1,MAX(1,COLUMN()-2+1-Varsayımlar!$D$36)) -> 1650000 | AL12: =SUM(B12:AK12) -> 59400000
A13: Değişken giderler (hammadde, ambalaj, komisyon, kargo) | B13: =-(B7*(1-Varsayımlar!$C$33)+B8*(1-Varsayımlar!$C$34)+B9*(1-Varsayımlar!$C$35)+B10*(1-Varsayımlar!$C$36)) -> -830000 | C13: =-(C7*(1-Varsayımlar!$C$33)+C8*(1-Varsayımlar!$C$34)+C9*(1-Varsayımlar!$C$35)+C10*(1-Varsayımlar!$C$36)) -> -830000 | D13: =-(D7*(1-Varsayımlar!$C$33)+D8*(1-Varsayımlar!$C$34)+D9*(1-Varsayımlar!$C$35)+D10*(1-Varsayımlar!$C$36)) -> -830000 | E13: =-(E7*(1-Varsayımlar!$C$33)+E8*(1-Varsayımlar!$C$34)+E9*(1-Varsayımlar!$C$35)+E10*(1-Varsayımlar!$C$36)) -> -830000 | F13: =-(F7*(1-Varsayımlar!$C$33)+F8*(1-Varsayımlar!$C$34)+F9*(1-Varsayımlar!$C$35)+F10*(1-Varsayımlar!$C$36)) -> -830000 | G13: =-(G7*(1-Varsayımlar!$C$33)+G8*(1-Varsayımlar!$C$34)+G9*(1-Varsayımlar!$C$35)+G10*(1-Varsayımlar!$C$36)) -> -830000 | H13: =-(H7*(1-Varsayımlar!$C$33)+H8*(1-Varsayımlar!$C$34)+H9*(1-Varsayımlar!$C$35)+H10*(1-Varsayımlar!$C$36)) -> -830000 | I13: =-(I7*(1-Varsayımlar!$C$33)+I8*(1-Varsayımlar!$C$34)+I9*(1-Varsayımlar!$C$35)+I10*(1-Varsayımlar!$C$36)) -> -830000 | ... AK13: =-(AK7*(1-Varsayımlar!$C$33)+AK8*(1-Varsayımlar!$C$34)+AK9*(1-Varsayımlar!$C$35)+AK10*(1-Varsayımlar!$C$36)) -> -830000 | AL13: =SUM(B13:AK13) -> -29880000
A14: BRÜT KÂR | B14: =B11+B13 -> 820000 | C14: =C11+C13 -> 820000 | D14: =D11+D13 -> 820000 | E14: =E11+E13 -> 820000 | F14: =F11+F13 -> 820000 | G14: =G11+G13 -> 820000 | H14: =H11+H13 -> 820000 | I14: =I11+I13 -> 820000 | ... AK14: =AK11+AK13 -> 820000 | AL14: =SUM(B14:AK14) -> 29520000
A15: Brüt (katkı) marjı % | B15: =IF(B11>0,B14/B11,0) -> 0.4969697 | C15: =IF(C11>0,C14/C11,0) -> 0.4969697 | D15: =IF(D11>0,D14/D11,0) -> 0.4969697 | E15: =IF(E11>0,E14/E11,0) -> 0.4969697 | F15: =IF(F11>0,F14/F11,0) -> 0.4969697 | G15: =IF(G11>0,G14/G11,0) -> 0.4969697 | H15: =IF(H11>0,H14/H11,0) -> 0.4969697 | I15: =IF(I11>0,I14/I11,0) -> 0.4969697 | ... AK15: =IF(AK11>0,AK14/AK11,0) -> 0.4969697 | AL15: =AVERAGE(B15:AK15) -> 0.4969697
A17: Sabit giderler
A18: Kira — fabrika (KDV dahil) | B18: =-Varsayımlar!$B$14*(1+Varsayımlar!$B$11)^B$5 -> -150000 | C18: =-Varsayımlar!$B$14*(1+Varsayımlar!$B$11)^C$5 -> -150000 | D18: =-Varsayımlar!$B$14*(1+Varsayımlar!$B$11)^D$5 -> -150000 | E18: =-Varsayımlar!$B$14*(1+Varsayımlar!$B$11)^E$5 -> -150000 | F18: =-Varsayımlar!$B$14*(1+Varsayımlar!$B$11)^F$5 -> -150000 | G18: =-Varsayımlar!$B$14*(1+Varsayımlar!$B$11)^G$5 -> -150000 | H18: =-Varsayımlar!$B$14*(1+Varsayımlar!$B$11)^H$5 -> -150000 | I18: =-Varsayımlar!$B$14*(1+Varsayımlar!$B$11)^I$5 -> -150000 | ... AK18: =-Varsayımlar!$B$14*(1+Varsayımlar!$B$11)^AK$5 -> -150000 | AL18: =SUM(B18:AK18) -> -5400000
A19: OSB / site aidatı | B19: =-Varsayımlar!$B$15*(1+Varsayımlar!$B$11)^B$5 -> -7000 | C19: =-Varsayımlar!$B$15*(1+Varsayımlar!$B$11)^C$5 -> -7000 | D19: =-Varsayımlar!$B$15*(1+Varsayımlar!$B$11)^D$5 -> -7000 | E19: =-Varsayımlar!$B$15*(1+Varsayımlar!$B$11)^E$5 -> -7000 | F19: =-Varsayımlar!$B$15*(1+Varsayımlar!$B$11)^F$5 -> -7000 | G19: =-Varsayımlar!$B$15*(1+Varsayımlar!$B$11)^G$5 -> -7000 | H19: =-Varsayımlar!$B$15*(1+Varsayımlar!$B$11)^H$5 -> -7000 | I19: =-Varsayımlar!$B$15*(1+Varsayımlar!$B$11)^I$5 -> -7000 | ... AK19: =-Varsayımlar!$B$15*(1+Varsayımlar!$B$11)^AK$5 -> -7000 | AL19: =SUM(B19:AK19) -> -252000
A20: Personel — mevcut maaşlar (kurucu maaşı dahil) | B20: =-Varsayımlar!$B$16*(1+Varsayımlar!$B$11)^B$5 -> -110000 | C20: =-Varsayımlar!$B$16*(1+Varsayımlar!$B$11)^C$5 -> -110000 | D20: =-Varsayımlar!$B$16*(1+Varsayımlar!$B$11)^D$5 -> -110000 | E20: =-Varsayımlar!$B$16*(1+Varsayımlar!$B$11)^E$5 -> -110000 | F20: =-Varsayımlar!$B$16*(1+Varsayımlar!$B$11)^F$5 -> -110000 | G20: =-Varsayımlar!$B$16*(1+Varsayımlar!$B$11)^G$5 -> -110000 | H20: =-Varsayımlar!$B$16*(1+Varsayımlar!$B$11)^H$5 -> -110000 | I20: =-Varsayımlar!$B$16*(1+Varsayımlar!$B$11)^I$5 -> -110000 | ... AK20: =-Varsayımlar!$B$16*(1+Varsayımlar!$B$11)^AK$5 -> -110000 | AL20: =SUM(B20:AK20) -> -3960000
A21: Personel — stopaj / SGK | B21: =-Varsayımlar!$B$17*(1+Varsayımlar!$B$11)^B$5 -> -30000 | C21: =-Varsayımlar!$B$17*(1+Varsayımlar!$B$11)^C$5 -> -30000 | D21: =-Varsayımlar!$B$17*(1+Varsayımlar!$B$11)^D$5 -> -30000 | E21: =-Varsayımlar!$B$17*(1+Varsayımlar!$B$11)^E$5 -> -30000 | F21: =-Varsayımlar!$B$17*(1+Varsayımlar!$B$11)^F$5 -> -30000 | G21: =-Varsayımlar!$B$17*(1+Varsayımlar!$B$11)^G$5 -> -30000 | H21: =-Varsayımlar!$B$17*(1+Varsayımlar!$B$11)^H$5 -> -30000 | I21: =-Varsayımlar!$B$17*(1+Varsayımlar!$B$11)^I$5 -> -30000 | ... AK21: =-Varsayımlar!$B$17*(1+Varsayımlar!$B$11)^AK$5 -> -30000 | AL21: =SUM(B21:AK21) -> -1080000
A22: Personel — planlanan part-time | B22: =-Varsayımlar!$B$18*(1+Varsayımlar!$B$11)^B$5 -> -20000 | C22: =-Varsayımlar!$B$18*(1+Varsayımlar!$B$11)^C$5 -> -20000 | D22: =-Varsayımlar!$B$18*(1+Varsayımlar!$B$11)^D$5 -> -20000 | E22: =-Varsayımlar!$B$18*(1+Varsayımlar!$B$11)^E$5 -> -20000 | F22: =-Varsayımlar!$B$18*(1+Varsayımlar!$B$11)^F$5 -> -20000 | G22: =-Varsayımlar!$B$18*(1+Varsayımlar!$B$11)^G$5 -> -20000 | H22: =-Varsayımlar!$B$18*(1+Varsayımlar!$B$11)^H$5 -> -20000 | I22: =-Varsayımlar!$B$18*(1+Varsayımlar!$B$11)^I$5 -> -20000 | ... AK22: =-Varsayımlar!$B$18*(1+Varsayımlar!$B$11)^AK$5 -> -20000 | AL22: =SUM(B22:AK22) -> -720000
A23: Enerji (elektrik, su, gaz) | B23: =-Varsayımlar!$B$19*(1+Varsayımlar!$B$11)^B$5 -> -15000 | C23: =-Varsayımlar!$B$19*(1+Varsayımlar!$B$11)^C$5 -> -15000 | D23: =-Varsayımlar!$B$19*(1+Varsayımlar!$B$11)^D$5 -> -15000 | E23: =-Varsayımlar!$B$19*(1+Varsayımlar!$B$11)^E$5 -> -15000 | F23: =-Varsayımlar!$B$19*(1+Varsayımlar!$B$11)^F$5 -> -15000 | G23: =-Varsayımlar!$B$19*(1+Varsayımlar!$B$11)^G$5 -> -15000 | H23: =-Varsayımlar!$B$19*(1+Varsayımlar!$B$11)^H$5 -> -15000 | I23: =-Varsayımlar!$B$19*(1+Varsayımlar!$B$11)^I$5 -> -15000 | ... AK23: =-Varsayımlar!$B$19*(1+Varsayımlar!$B$11)^AK$5 -> -15000 | AL23: =SUM(B23:AK23) -> -540000
A24: Muhasebe / mali müşavir | B24: =-Varsayımlar!$B$20*(1+Varsayımlar!$B$11)^B$5 -> -10000 | C24: =-Varsayımlar!$B$20*(1+Varsayımlar!$B$11)^C$5 -> -10000 | D24: =-Varsayımlar!$B$20*(1+Varsayımlar!$B$11)^D$5 -> -10000 | E24: =-Varsayımlar!$B$20*(1+Varsayımlar!$B$11)^E$5 -> -10000 | F24: =-Varsayımlar!$B$20*(1+Varsayımlar!$B$11)^F$5 -> -10000 | G24: =-Varsayımlar!$B$20*(1+Varsayımlar!$B$11)^G$5 -> -10000 | H24: =-Varsayımlar!$B$20*(1+Varsayımlar!$B$11)^H$5 -> -10000 | I24: =-Varsayımlar!$B$20*(1+Varsayımlar!$B$11)^I$5 -> -10000 | ... AK24: =-Varsayımlar!$B$20*(1+Varsayımlar!$B$11)^AK$5 -> -10000 | AL24: =SUM(B24:AK24) -> -360000
A25: Yazılım abonelikleri | B25: =-Varsayımlar!$B$21*(1+Varsayımlar!$B$11)^B$5 -> -3000 | C25: =-Varsayımlar!$B$21*(1+Varsayımlar!$B$11)^C$5 -> -3000 | D25: =-Varsayımlar!$B$21*(1+Varsayımlar!$B$11)^D$5 -> -3000 | E25: =-Varsayımlar!$B$21*(1+Varsayımlar!$B$11)^E$5 -> -3000 | F25: =-Varsayımlar!$B$21*(1+Varsayımlar!$B$11)^F$5 -> -3000 | G25: =-Varsayımlar!$B$21*(1+Varsayımlar!$B$11)^G$5 -> -3000 | H25: =-Varsayımlar!$B$21*(1+Varsayımlar!$B$11)^H$5 -> -3000 | I25: =-Varsayımlar!$B$21*(1+Varsayımlar!$B$11)^I$5 -> -3000 | ... AK25: =-Varsayımlar!$B$21*(1+Varsayımlar!$B$11)^AK$5 -> -3000 | AL25: =SUM(B25:AK25) -> -108000
A26: Sigorta (şu an yalnız araç) | B26: =-Varsayımlar!$B$22*(1+Varsayımlar!$B$11)^B$5 -> -3000 | C26: =-Varsayımlar!$B$22*(1+Varsayımlar!$B$11)^C$5 -> -3000 | D26: =-Varsayımlar!$B$22*(1+Varsayımlar!$B$11)^D$5 -> -3000 | E26: =-Varsayımlar!$B$22*(1+Varsayımlar!$B$11)^E$5 -> -3000 | F26: =-Varsayımlar!$B$22*(1+Varsayımlar!$B$11)^F$5 -> -3000 | G26: =-Varsayımlar!$B$22*(1+Varsayımlar!$B$11)^G$5 -> -3000 | H26: =-Varsayımlar!$B$22*(1+Varsayımlar!$B$11)^H$5 -> -3000 | I26: =-Varsayımlar!$B$22*(1+Varsayımlar!$B$11)^I$5 -> -3000 | ... AK26: =-Varsayımlar!$B$22*(1+Varsayımlar!$B$11)^AK$5 -> -3000 | AL26: =SUM(B26:AK26) -> -108000
